Workbook

Sheet Sheet4
IU65534: English 4.1

Sheet Sheet3

Sheet Sheet2

Sheet Instructions
A1: 4.2
B2: AWWA Water Loss Control Committee (WLCC) Free Water Audit Software v4.2
C4: PURPOSE: This spreadsheet-based water audit tool is designed to help quantify and track water losses associated with water distribution systems and identify areas for improved efficiency and cost recovery. It provides a "top-down" summary water audit format, and is not meant to take the place of a full-scale, comprehensive water audit format.
C7: USE: The spreadsheet contains several separate worksheets. Sheets can be accessed using the tabs towards the bottom of the screen, or by clicking the buttons on the left below. Descriptions of each sheet are also given below.
C10: THE FOLLOWING KEY APPLIES THROUGHOUT: | G10: Value can be entered by user
G12: Value calculated based on input data
G14: These cells contain recommended default values
C16: Please begin by providing the following information, then proceed through each sheet in the workbook:
C18: NAME OF CITY OR UTILITY: | D18: Lehighton Water Authority | I18: COUNTRY: | J18: United Stetes
C20: REPORTING YEAR: | D20: 2013 | F20: START DATE(MM/YYYY): | G20: 41275 | I20: END DATE(MM/YYYY): | K20: 41609
C22: NAME OF CONTACT PERSON: | D22: Armen Galasso | F22: E-MAIL: | G22: waterlwa@ptd.net | K22: TELEPHONE: | M22: 6103771912
L23: Ext.
C24: PLEASE SELECT PREFERRED REPORTING UNITS FOR WATER VOLUME: | G24: Million gallons (US)
C26: Click to advance to sheet… | G26: Click here: for help about units and conversions
D27: The current sheet
D29: Enter the required data on this worksheet to calculate the water balance
D31: The values entered in the Reporting Worksheet are used to populate the water balance
D33: Depending on the confidence of audit inputs, a grading is assigned to the audit score
D35: Diagrams depicting possible customer service connection configurations
D37: Use this sheet to understand terms used in the audit process
D39: Use this sheet to interpret the results of the audit validity score and performance indicators
C41: Comments: | D41: D-89-93 CP
K45: If you have questions or comments regarding the software please contact us at: | L45: wlc@awwa.org

Sheet Reporting Worksheet
A1: 0
B2: AWWA WLCC Free Water Audit Software: Reporting Worksheet
C4: Water Audit Report for: | D4: =IF(ISBLANK(Instructions!D18),"",Instructions!D18) -> Lehighton Water Authority
C5: Reporting Year: | D5: =IF(ISBLANK(Instructions!D20),"",Instructions!D20) -> 2013 | G5: =IF(OR(ISBLANK(Instructions!G20),ISBLANK(Instructions!K20)),"",MONTH(Instructions!G20)&"/"&YEAR(Instructions!G20)&" - "&MONTH(Instructions!K20)&"/"&YEAR(Instructions!K20)) -> 1/2013 - 12/2013
G9: =IF(ISBLANK(Instructions!G24),"PLEASE CHOOSE REPORTING UNITS FROM THE INSTRUCTIONS SHEET BEFORE ENTERING DATA","All volumes to be entered as: "&UPPER(Instructions!$G$24)&" PER YEAR") -> All volumes to be entered as: MILLION GALLONS (US) PER YEAR
C12: WATER SUPPLIED | D12: << Enter grading in column 'E'
C14: Volume from own sources: | E14: 7 | G14: 285.656 | I14: =IF(Instructions!$G$24="Million gallons (US)","Million gallons (US)/yr (MG/Yr)",IF(Instructions!$G$24="Megalitres (thousand cubic metres)","Megalitres/yr (or ML/Yr)",IF(Instructions!$G$24="Acre-feet","acre-ft/yr",""))) -> Million gallons (US)/yr (MG/Yr)
C15: Master meter error adjustment (enter positive value): | E15: 1 | G15: 0 | K15: =IF(AND(NOT(ISBLANK(G15)),G15>0,ISBLANK(I15)),"<---Enter adjustment type",IF(Instructions!$G$24="million gallons (US)","MG/Yr",IF(Instructions!$G$24="Megalitres (thousand cubic metres)","ML/Yr",IF(Instructions!$G$24="acre-feet","acre-ft/yr","")))) -> MG/Yr
C16: Water imported: | E16: n/a | G16: 0 | I16: =IF(Instructions!$G$24="million gallons (US)","MG/Yr",IF(Instructions!$G$24="Megalitres (thousand cubic metres)","ML/Yr",IF(Instructions!$G$24="acre-feet","acre-ft/yr",""))) -> MG/Yr | J16: =IF(AND(G14=G16,G19<>0),"Volume identical to own sources","")
C17: Water exported: | E17: n/a | G17: 0 | I17: =IF(Instructions!$G$24="million gallons (US)","MG/Yr",IF(Instructions!$G$24="Megalitres (thousand cubic metres)","ML/Yr",IF(Instructions!$G$24="acre-feet","acre-ft/yr",""))) -> MG/Yr
C19: WATER SUPPLIED: | G19: =G14+IF(I15="under-registered",+G15,IF(I15="over-registered",-G15,))+G16-G17 -> 285.656 | I19: =IF(Instructions!$G$24="million gallons (US)","MG/Yr",IF(Instructions!$G$24="Megalitres (thousand cubic metres)","ML/Yr",IF(Instructions!$G$24="acre-feet","acre-ft/yr",""))) -> MG/Yr
E21: .
C22: AUTHORIZED CONSUMPTION
C23: Billed metered: | E23: 6 | G23: 161.2 | I23: =IF(Instructions!$G$24="million gallons (US)","MG/Yr",IF(Instructions!$G$24="Megalitres (thousand cubic metres)","ML/Yr",IF(Instructions!$G$24="acre-feet","acre-ft/yr",""))) -> MG/Yr
C24: Billed unmetered: | E24: n/a | G24: 0 | I24: =IF(Instructions!$G$24="million gallons (US)","MG/Yr",IF(Instructions!$G$24="Megalitres (thousand cubic metres)","ML/Yr",IF(Instructions!$G$24="acre-feet","acre-ft/yr",""))) -> MG/Yr
C25: Unbilled metered: | E25: 9 | G25: 1.467 | I25: =IF(Instructions!$G$24="million gallons (US)","MG/Yr",IF(Instructions!$G$24="Megalitres (thousand cubic metres)","ML/Yr",IF(Instructions!$G$24="acre-feet","acre-ft/yr",""))) -> MG/Yr | J25: Pcnt: | L25: Value:
C26: Unbilled unmetered: | G26: =IF(OR(P26=1,AND(P26=2,L26=0)),J26*$G$19,L26) -> 3.5707 | I26: =IF(Instructions!$G$24="million gallons (US)","MG/Yr",IF(Instructions!$G$24="Megalitres (thousand cubic metres)","ML/Yr",IF(Instructions!$G$24="acre-feet","acre-ft/yr",""))) -> MG/Yr | J26: 0.0125 | P26: 1
L27: 24061
C28: =IF(P26=1," Default option selected for Unbilled unmetered - a grading of 5 is applied but not displayed",IF(P26=2,IF(L26>0.125*G19," Unbilled Unmetered volume entered is greater than the recommended default value",IF(L26=0,"Enter a positive value, otherwise a default percentage of 1.25% and a grading of 5 is applied","")))) -> Default option selected for Unbilled unmetered - a grading of 5 is applied but not displayed
C30: AUTHORIZED CONSUMPTION: | G30: =SUM(G23:G26) -> 166.2377 | I30: =IF(Instructions!$G$24="million gallons (US)","MG/Yr",IF(Instructions!$G$24="Megalitres (thousand cubic metres)","ML/Yr",IF(Instructions!$G$24="acre-feet","acre-ft/yr",""))) -> MG/Yr
C32: =IF(AND(G30>=G19,(G30<>0))," Check input values; WATER SUPPLIED should be greater than AUTHORIZED CONSUMPTION","")
C35: WATER LOSSES (Water Supplied - Authorized Consumption) | G35: =G19-G30 -> 119.4183 | I35: =IF(Instructions!$G$24="million gallons (US)","MG/Yr",IF(Instructions!$G$24="Megalitres (thousand cubic metres)","ML/Yr",IF(Instructions!$G$24="acre-feet","acre-ft/yr",""))) -> MG/Yr
C37: Apparent Losses | J37: Pcnt: | L37: Value:
C38: Unauthorized consumption: | G38: =IF(P38=1,J38*$G$19,L38) -> 0.71414 | I38: =IF(Instructions!$G$24="million gallons (US)","MG/Yr",IF(Instructions!$G$24="Megalitres (thousand cubic metres)","ML/Yr",IF(Instructions!$G$24="acre-feet","acre-ft/yr",""))) -> MG/Yr | J38: 0.0025 | P38: 1
C40: =IF(P38=1," Default option selected for unauthorized consumption - a grading of 5 is applied but not displayed ",IF(P38=2,IF(L38>0.025*G19,"Unauthorized consumption volume entered is greater than the recommended default value",IF(L38=0,"Enter a positive value, otherwise a default percentage of 0.25% and a grading of 5 is applied","")))) -> Default option selected for unauthorized consumption - a grading of 5 is applied but not displayed
C42: Customer metering inaccuracies: | E42: 3 | G42: =IF(P42=1,((G23+G25)/(1-J42))-(G23+G25),L42) -> 8.5614211 | I42: =IF(Instructions!$G$24="million gallons (US)","MG/Yr",IF(Instructions!$G$24="Megalitres (thousand cubic metres)","ML/Yr",IF(Instructions!$G$24="acre-feet","acre-ft/yr",""))) -> MG/Yr | J42: 0.05 | P42: 1
C43: Systematic data handling errors: | E43: 4 | G43: 0 | I43: =IF(Instructions!$G$24="million gallons (US)","MG/Yr",IF(Instructions!$G$24="Megalitres (thousand cubic metres)","ML/Yr",IF(Instructions!$G$24="acre-feet","acre-ft/yr",""))) -> MG/Yr
L44: =IF(AND($P$42=1,ISBLANK($J$42)),"Enter a percentage less than 10% in the red cell (J42), or select 'Value' option","Choose this option to enter a percentage of billed metered consumption. This is NOT a default value") -> Choose this option to enter a percentage of billed metered consumption. This is NOT a default value
C45: =IF(OR(G19=0,E43="n/a"),"",IF(OR(ISBLANK(G43),G43=0),"Systematic data handling errors are likely, please enter a non-zero value; otherwise grade = 5","")) -> Systematic data handling errors are likely, please enter a non-zero value; otherwise grade = 5
C47: Apparent Losses: | G47: =G38+G42+G43 -> 9.2755611
C49: =IF(AND(G47>=G35,(G47<>0)),"Check input values; APPARENT LOSSES should be less than WATER LOSSES","")
C51: Real Losses (Current Annual Real Losses or CARL)
C52: Real Losses = Water Losses - Apparent Losses: | G52: =G19-(G30+G47) -> 110.14274 | I52: =IF(Instructions!$G$24="million gallons (US)","MG/Yr",IF(Instructions!$G$24="Megalitres (thousand cubic metres)","ML/Yr",IF(Instructions!$G$24="acre-feet","acre-ft/yr",""))) -> MG/Yr
C54: WATER LOSSES: | G54: =G47+G52 -> 119.4183 | I54: =IF(Instructions!$G$24="million gallons (US)","MG/Yr",IF(Instructions!$G$24="Megalitres (thousand cubic metres)","ML/Yr",IF(Instructions!$G$24="acre-feet","acre-ft/yr",""))) -> MG/Yr
C57: NON-REVENUE WATER
C58: NON-REVENUE WATER: | G58: =G47+G52+G25+G26 -> 124.456 | I58: =IF(Instructions!$G$24="million gallons (US)","MG/Yr",IF(Instructions!$G$24="Megalitres (thousand cubic metres)","ML/Yr",IF(Instructions!$G$24="acre-feet","acre-ft/yr",""))) -> MG/Yr
C59: = Total Water Loss + Unbilled Metered + Unbilled Unmetered
C60: SYSTEM DATA
C62: Length of mains: | E62: 3 | G62: 43 | I62: =IF(ISBLANK(Instructions!$G$24),"",IF(Instructions!$G$24="Megalitres (thousand cubic metres)","kilometers","miles")) -> miles
C63: Number of active AND inactive service connections: | E63: 3 | G63: 3700
...

Sheet Water Balance
B2: AWWA WLCC Free Water Audit Software: Water Balance | F2: Water Audit Report For: | G2: Report Yr:
F3: =IF(ISBLANK(Instructions!D18),"",Instructions!D18) -> Lehighton Water Authority | G3: =IF(ISBLANK(Instructions!D20),"",Instructions!D20) -> 2013
E4: =IF(ISBLANK(Instructions!H24),"","All Units in "&Instructions!H24)
C5: Water Exported | F5: Billed Water Exported
C6: ='Reporting Worksheet'!G17 -> 0
E7: Billed Authorized Consumption | F7: Billed Metered Consumption (inc. water exported) | G7: Revenue Water
F8: ='Reporting Worksheet'!G23 -> 161.2
B9: Own Sources | D9: Authorized Consumption | E9: ='Reporting Worksheet'!G23+'Reporting Worksheet'!G24 -> 161.2 | F9: Billed Unmetered Consumption | G9: =SUM(F8+F10) -> 161.2
B10: (Adjusted for known errors) | F10: ='Reporting Worksheet'!G24 -> 0
D11: ='Reporting Worksheet'!G30 -> 166.2377 | E11: Unbilled Authorized Consumption | F11: Unbilled Metered Consumption | G11: Non-Revenue Water (NRW)
F12: ='Reporting Worksheet'!G25 -> 1.467
B13: ='Reporting Worksheet'!G14+IF('Reporting Worksheet'!I15="under-registered",+'Reporting Worksheet'!G15,IF('Reporting Worksheet'!I15="over-registered",-'Reporting Worksheet'!G15,)) -> 285.656 | E13: ='Reporting Worksheet'!G25+'Reporting Worksheet'!G26 -> 5.0377 | F13: Unbilled Unmetered Consumption
F14: ='Reporting Worksheet'!G26 -> 3.5707
C15: Water Supplied | F15: Unauthorized Consumption | G15: ='Reporting Worksheet'!G25+'Reporting Worksheet'!G26+'Reporting Worksheet'!G47+'Reporting Worksheet'!G52 -> 124.456
E16: Apparent Losses | F16: ='Reporting Worksheet'!G38 -> 0.71414
C17: ='Reporting Worksheet'!G19 -> 285.656 | E17: ='Reporting Worksheet'!G47 -> 9.2755611 | F17: Customer Metering Inaccuracies
F18: ='Reporting Worksheet'!G42 -> 8.5614211
F19: Systematic Data Handling Errors
D20: Water Losses | F20: ='Reporting Worksheet'!G43 -> 0
B21: Water Imported | D21: ='Reporting Worksheet'!G54 -> 119.4183 | F21: Leakage on Transmission and/or Distribution Mains
E22: Real Losses | F22: Not broken down
B23: ='Reporting Worksheet'!G16 -> 0 | E23: ='Reporting Worksheet'!G52 -> 110.14274 | F23: Leakage and Overflows at Utility's Storage Tanks
F24: Not broken down
F25: Leakage on Service Connections
F26: Not broken down

Sheet GradingAssessment
G2: Score
C3: Grade | D3: Weight | E3: adjWeight | F3: adjFactor | G3: Grade*Weight | H3: droppedPts | I3: uniqueRank | K3: Needs grade | L3: Has grade | M3: Grade Problem
B4: Volume from own sources: | C4: =IF('Reporting Worksheet'!E14="n/a",0,'Reporting Worksheet'!E14) -> 7 | D4: =IF('Reporting Worksheet'!G14=0,0,IF('Reporting Worksheet'!G14>'Reporting Worksheet'!G16,20,8)) -> 20 | E4: =D4/$D$23 -> 28.169014 | F4: =IF(D4<>0,E4/10,0) -> 2.8169014 | G4: =C4*F4 -> 19.71831 | H4: =IF(F4=0,0,E4-G4) -> 8.4507042 | I4: {=SUM(1*(H4<$H$4:$H$21))+1+IF(ROW(H4)-ROW($H$4)=0,0,SUM(1*(H4=OFFSET($H$4,0,0,INDEX(ROW(H4)-ROW($H$4)+1,1)-1,1))))} -> 1 | J4: Volume from own sources | K4: =IF(D4<>0,1,0) -> 1 | L4: =IF(C4>0,1,0) -> 1 | M4: =IF(AND(K4=1,L4=0),1,0) -> 0
B5: Master meter error adjustment: | C5: =IF('Reporting Worksheet'!E15="n/a",0,'Reporting Worksheet'!E15) -> 1 | D5: =IF('Reporting Worksheet'!G15=0,0,8) -> 0 | E5: =D5/$D$23 -> 0 | F5: =IF(D5<>0,E5/10,0) -> 0 | G5: =C5*F5 -> 0 | H5: =IF(F5=0,0,E5-G5) -> 0 | I5: {=SUM(1*(H5<$H$4:$H$21))+1+IF(ROW(H5)-ROW($H$4)=0,0,SUM(1*(H5=OFFSET($H$4,0,0,INDEX(ROW(H5)-ROW($H$4)+1,1)-1,1))))} -> 15 | J5: Master meter error adjustment | K5: =IF(D5<>0,1,0) -> 0 | L5: =IF(C5>0,1,0) -> 1 | M5: =IF(AND(K5=1,L5=0),1,0) -> 0
B6: Water imported: | C6: =IF('Reporting Worksheet'!E16="n/a",0,'Reporting Worksheet'!E16) -> 0 | D6: =IF('Reporting Worksheet'!G16=0,0,IF('Reporting Worksheet'!G16>'Reporting Worksheet'!G14,20,8)) -> 0 | E6: =D6/$D$23 -> 0 | F6: =IF(D6<>0,E6/10,0) -> 0 | G6: =C6*F6 -> 0 | H6: =IF(F6=0,0,E6-G6) -> 0 | I6: {=SUM(1*(H6<$H$4:$H$21))+1+IF(ROW(H6)-ROW($H$4)=0,0,SUM(1*(H6=OFFSET($H$4,0,0,INDEX(ROW(H6)-ROW($H$4)+1,1)-1,1))))} -> 16 | J6: Water imported | K6: =IF(D6<>0,1,0) -> 0 | L6: =IF(C6>0,1,0) -> 0 | M6: =IF(AND(K6=1,L6=0),1,0) -> 0
B7: Water exported: | C7: =IF('Reporting Worksheet'!E17="n/a",0,'Reporting Worksheet'!E17) -> 0 | D7: =IF('Reporting Worksheet'!G17=0,0,8) -> 0 | E7: =D7/$D$23 -> 0 | F7: =IF(D7<>0,E7/10,0) -> 0 | G7: =C7*F7 -> 0 | H7: =IF(F7=0,0,E7-G7) -> 0 | I7: {=SUM(1*(H7<$H$4:$H$21))+1+IF(ROW(H7)-ROW($H$4)=0,0,SUM(1*(H7=OFFSET($H$4,0,0,INDEX(ROW(H7)-ROW($H$4)+1,1)-1,1))))} -> 17 | J7: Water exported | K7: =IF(D7<>0,1,0) -> 0 | L7: =IF(C7>0,1,0) -> 0 | M7: =IF(AND(K7=1,L7=0),1,0) -> 0
B8: Billed metered: | C8: =IF('Reporting Worksheet'!E23="n/a",0,'Reporting Worksheet'!E23) -> 6 | D8: =IF(AND('Reporting Worksheet'!E23="n/a",'Reporting Worksheet'!G23=0),0,8) -> 8 | E8: =D8/$D$23 -> 11.267606 | F8: =IF(D8<>0,E8/10,0) -> 1.1267606 | G8: =C8*F8 -> 6.7605634 | H8: =IF(F8=0,0,E8-G8) -> 4.5070423 | I8: {=SUM(1*(H8<$H$4:$H$21))+1+IF(ROW(H8)-ROW($H$4)=0,0,SUM(1*(H8=OFFSET($H$4,0,0,INDEX(ROW(H8)-ROW($H$4)+1,1)-1,1))))} -> 3 | J8: Billed metered | K8: =IF(D8<>0,1,0) -> 1 | L8: =IF(C8>0,1,0) -> 1 | M8: =IF(AND(K8=1,L8=0),1,0) -> 0
B9: Billed unmetered: | C9: =IF('Reporting Worksheet'!E24="n/a",0,'Reporting Worksheet'!E24) -> 0 | D9: =IF('Reporting Worksheet'!G24=0,0,6) -> 0 | E9: =D9/$D$23 -> 0 | F9: =IF(D9<>0,E9/10,0) -> 0 | G9: =C9*F9 -> 0 | H9: =IF(F9=0,0,E9-G9) -> 0 | I9: {=SUM(1*(H9<$H$4:$H$21))+1+IF(ROW(H9)-ROW($H$4)=0,0,SUM(1*(H9=OFFSET($H$4,0,0,INDEX(ROW(H9)-ROW($H$4)+1,1)-1,1))))} -> 18 | J9: Billed unmetered | K9: =IF(D9<>0,1,0) -> 0 | L9: =IF(C9>0,1,0) -> 0 | M9: =IF(AND(K9=1,L9=0),1,0) -> 0
B10: Unbilled metered: | C10: =IF('Reporting Worksheet'!E25="n/a",0,'Reporting Worksheet'!E25) -> 9 | D10: =IF('Reporting Worksheet'!G25=0,0,6) -> 6 | E10: =D10/$D$23 -> 8.4507042 | F10: =IF(D10<>0,E10/10,0) -> 0.84507042 | G10: =C10*F10 -> 7.6056338 | H10: =IF(F10=0,0,E10-G10) -> 0.84507042 | I10: {=SUM(1*(H10<$H$4:$H$21))+1+IF(ROW(H10)-ROW($H$4)=0,0,SUM(1*(H10=OFFSET($H$4,0,0,INDEX(ROW(H10)-ROW($H$4)+1,1)-1,1))))} -> 13 | J10: Unbilled metered | K10: =IF(D10<>0,1,0) -> 1 | L10: =IF(C10>0,1,0) -> 1 | M10: =IF(AND(K10=1,L10=0),1,0) -> 0
A11: D | B11: Unbilled unmetered: | C11: =IF(OR('Reporting Worksheet'!P26=1,AND('Reporting Worksheet'!P26=2,'Reporting Worksheet'!L26=0)),5,'Reporting Worksheet'!E26) -> 5 | D11: 1 | E11: =D11/$D$23 -> 1.4084507 | F11: =IF(D11<>0,E11/10,0) -> 0.14084507 | G11: =C11*F11 -> 0.70422535 | H11: =IF(F11=0,0,E11-G11) -> 0.70422535 | I11: {=SUM(1*(H11<$H$4:$H$21))+1+IF(ROW(H11)-ROW($H$4)=0,0,SUM(1*(H11=OFFSET($H$4,0,0,INDEX(ROW(H11)-ROW($H$4)+1,1)-1,1))))} -> 14 | J11: Unbilled unmetered | K11: =IF(D11<>0,1,0) -> 1 | L11: =IF(C11>0,1,0) -> 1 | M11: =IF(AND(K11=1,L11=0),1,0) -> 0
A12: D | B12: Unauthorized consumption: | C12: =IF(OR('Reporting Worksheet'!P38=1,AND('Reporting Worksheet'!P38=2,'Reporting Worksheet'!L38=0)),5,'Reporting Worksheet'!E38) -> 5 | D12: 4 | E12: =D12/$D$23 -> 5.6338028 | F12: =IF(D12<>0,E12/10,0) -> 0.56338028 | G12: =C12*F12 -> 2.8169014 | H12: =IF(F12=0,0,E12-G12) -> 2.8169014 | I12: {=SUM(1*(H12<$H$4:$H$21))+1+IF(ROW(H12)-ROW($H$4)=0,0,SUM(1*(H12=OFFSET($H$4,0,0,INDEX(ROW(H12)-ROW($H$4)+1,1)-1,1))))} -> 4 | J12: Unauthorized consumption | K12: =IF(D12<>0,1,0) -> 1 | L12: =IF(C12>0,1,0) -> 1 | M12: =IF(AND(K12=1,L12=0),1,0) -> 0
B13: Customer metering inaccuracies: | C13: =IF('Reporting Worksheet'!E42="n/a",0,'Reporting Worksheet'!E42) -> 3 | D13: =IF(AND('Reporting Worksheet'!E42="n/a",'Reporting Worksheet'!G42=0),0,6) -> 6 | E13: =D13/$D$23 -> 8.4507042 | F13: =IF(D13<>0,E13/10,0) -> 0.84507042 | G13: =C13*F13 -> 2.5352113 | H13: =IF(F13=0,0,E13-G13) -> 5.915493 | I13: {=SUM(1*(H13<$H$4:$H$21))+1+IF(ROW(H13)-ROW($H$4)=0,0,SUM(1*(H13=OFFSET($H$4,0,0,INDEX(ROW(H13)-ROW($H$4)+1,1)-1,1))))} -> 2 | J13: Customer metering inaccuracies | K13: =IF(D13<>0,1,0) -> 1 | L13: =IF(C13>0,1,0) -> 1 | M13: =IF(AND(K13=1,L13=0),1,0) -> 0
B14: Systematic data handling errors: | C14: =IF('Reporting Worksheet'!E43="n/a",0,IF('Reporting Worksheet'!G43=0,5,'Reporting Worksheet'!E43)) -> 5 | D14: 4 | E14: =D14/$D$23 -> 5.6338028 | F14: =IF(D14<>0,E14/10,0) -> 0.56338028 | G14: =C14*F14 -> 2.8169014 | H14: =IF(F14=0,0,E14-G14) -> 2.8169014 | I14: {=SUM(1*(H14<$H$4:$H$21))+1+IF(ROW(H14)-ROW($H$4)=0,0,SUM(1*(H14=OFFSET($H$4,0,0,INDEX(ROW(H14)-ROW($H$4)+1,1)-1,1))))} -> 5 | J14: Systematic data handling errors | K14: =IF(D14<>0,1,0) -> 1 | L14: =IF(C14>0,1,0) -> 1 | M14: =IF(AND(K14=1,L14=0),1,0) -> 0
B15: Length of mains: | C15: ='Reporting Worksheet'!E62 -> 3 | D15: 1 | E15: =D15/$D$23 -> 1.4084507 | F15: =IF(D15<>0,E15/10,0) -> 0.14084507 | G15: =C15*F15 -> 0.42253521 | H15: =IF(F15=0,0,E15-G15) -> 0.98591549 | I15: {=SUM(1*(H15<$H$4:$H$21))+1+IF(ROW(H15)-ROW($H$4)=0,0,SUM(1*(H15=OFFSET($H$4,0,0,INDEX(ROW(H15)-ROW($H$4)+1,1)-1,1))))} -> 10 | J15: Length of mains | K15: =IF(D15<>0,1,0) -> 1 | L15: =IF(C15>0,1,0) -> 1 | M15: =IF(AND(K15=1,L15=0),1,0) -> 0
B16: Number of active AND inactive service connections: | C16: ='Reporting Worksheet'!E63 -> 3 | D16: 1 | E16: =D16/$D$23 -> 1.4084507 | F16: =IF(D16<>0,E16/10,0) -> 0.14084507 | G16: =C16*F16 -> 0.42253521 | H16: =IF(F16=0,0,E16-G16) -> 0.98591549 | I16: {=SUM(1*(H16<$H$4:$H$21))+1+IF(ROW(H16)-ROW($H$4)=0,0,SUM(1*(H16=OFFSET($H$4,0,0,INDEX(ROW(H16)-ROW($H$4)+1,1)-1,1))))} -> 11 | J16: Number of active AND inactive service connections | K16: =IF(D16<>0,1,0) -> 1 | L16: =IF(C16>0,1,0) -> 1 | M16: =IF(AND(K16=1,L16=0),1,0) -> 0
B17: Average length of customer service line: | C17: =IF('Reporting Worksheet'!E65="n/a",0,'Reporting Worksheet'!E65) -> 3 | D17: 1 | E17: =D17/$D$23 -> 1.4084507 | F17: =IF(D17<>0,E17/10,0) -> 0.14084507 | G17: =C17*F17 -> 0.42253521 | H17: =IF(F17=0,0,E17-G17) -> 0.98591549 | I17: {=SUM(1*(H17<$H$4:$H$21))+1+IF(ROW(H17)-ROW($H$4)=0,0,SUM(1*(H17=OFFSET($H$4,0,0,INDEX(ROW(H17)-ROW($H$4)+1,1)-1,1))))} -> 12 | J17: Average length of customer service line | K17: =IF(D17<>0,1,0) -> 1 | L17: =IF(C17>0,1,0) -> 1 | M17: =IF(AND(K17=1,L17=0),1,0) -> 0
B18: Average operating pressure: | C18: ='Reporting Worksheet'!E67 -> 2 | D18: 1 | E18: =D18/$D$23 -> 1.4084507 | F18: =IF(D18<>0,E18/10,0) -> 0.14084507 | G18: =C18*F18 -> 0.28169014 | H18: =IF(F18=0,0,E18-G18) -> 1.1267606 | I18: {=SUM(1*(H18<$H$4:$H$21))+1+IF(ROW(H18)-ROW($H$4)=0,0,SUM(1*(H18=OFFSET($H$4,0,0,INDEX(ROW(H18)-ROW($H$4)+1,1)-1,1))))} -> 9 | J18: Average operating pressure | K18: =IF(D18<>0,1,0) -> 1 | L18: =IF(C18>0,1,0) -> 1 | M18: =IF(AND(K18=1,L18=0),1,0) -> 0
B19: Total annual cost of operating water system: | C19: ='Reporting Worksheet'!E74 -> 8 | D19: 6 | E19: =D19/$D$23 -> 8.4507042 | F19: =IF(D19<>0,E19/10,0) -> 0.84507042 | G19: =C19*F19 -> 6.7605634 | H19: =IF(F19=0,0,E19-G19) -> 1.6901408 | I19: {=SUM(1*(H19<$H$4:$H$21))+1+IF(ROW(H19)-ROW($H$4)=0,0,SUM(1*(H19=OFFSET($H$4,0,0,INDEX(ROW(H19)-ROW($H$4)+1,1)-1,1))))} -> 6 | J19: Total annual cost of operating water system | K19: =IF(D19<>0,1,0) -> 1 | L19: =IF(C19>0,1,0) -> 1 | M19: =IF(AND(K19=1,L19=0),1,0) -> 0
B20: Customer retail unit cost (applied to Apparent Losses): | C20: ='Reporting Worksheet'!E75 -> 8 | D20: 6 | E20: =D20/$D$23 -> 8.4507042 | F20: =IF(D20<>0,E20/10,0) -> 0.84507042 | G20: =C20*F20 -> 6.7605634 | H20: =IF(F20=0,0,E20-G20) -> 1.6901408 | I20: {=SUM(1*(H20<$H$4:$H$21))+1+IF(ROW(H20)-ROW($H$4)=0,0,SUM(1*(H20=OFFSET($H$4,0,0,INDEX(ROW(H20)-ROW($H$4)+1,1)-1,1))))} -> 7 | J20: Customer retail unit cost (applied to Apparent Losses) | K20: =IF(D20<>0,1,0) -> 1 | L20: =IF(C20>0,1,0) -> 1 | M20: =IF(AND(K20=1,L20=0),1,0) -> 0
B21: Variable production cost (applied to Real Losses): | C21: =IF('Reporting Worksheet'!E76="n/a",0,'Reporting Worksheet'!E76) -> 8 | D21: 6 | E21: =D21/$D$23 -> 8.4507042 | F21: =IF(D21<>0,E21/10,0) -> 0.84507042 | G21: =C21*F21 -> 6.7605634 | H21: =IF(F21=0,0,E21-G21) -> 1.6901408 | I21: {=SUM(1*(H21<$H$4:$H$21))+1+IF(ROW(H21)-ROW($H$4)=0,0,SUM(1*(H21=OFFSET($H$4,0,0,INDEX(ROW(H21)-ROW($H$4)+1,1)-1,1))))} -> 8 | J21: Variable production cost (applied to Real Losses) | K21: =IF(D21<>0,1,0) -> 1 | L21: =IF(C21>0,1,0) -> 1 | M21: =IF(AND(K21=1,L21=0),1,0) -> 0
D22: =SUM(D4:D21) -> 71 | E22: =SUM(E4:E21) -> 100 | F22: =SUM(F4:F21) -> 10 | G22: =SUM(G4:G21) -> 64.788732 | M22: =SUM(M4:M21) -> 0
D23: =D22/100 -> 0.71
B25: Enter criteria in these cells | L25: =IF(SUM('Reporting Worksheet'!P26,'Reporting Worksheet'!P38)=2,2,IF(SUM('Reporting Worksheet'!P26,'Reporting Worksheet'!P38)=3,1,0)) -> 2 | M25: default(s) being used

Sheet Grading Matrix
C2: AWWA WLCC Free Water Audit Software: Grading Matrix
R3: =VLOOKUP(1,GradingAssessment!$I$4:$J$21,2,FALSE)&":" -> Volume from own sources:
C4: In the Reporting Worksheet, grades were assigned to each component of the audit to describe the confidence and accuracy of the input data. The grading assigned to each audit component and the corresponding recommended improvements and actions are highlighted in yellow. Audit accuracy is likely to be improved by prioritizing those items shown in red | R4: =VLOOKUP(2,GradingAssessment!$I$4:$J$21,2,FALSE)&":" -> Customer metering inaccuracies:
R5: =VLOOKUP(3,GradingAssessment!$I$4:$J$21,2,FALSE)&":" -> Billed metered:
C6: Grading
D7: n/a | E7: 1 | F7: 2 | G7: 3 | H7: 4 | I7: 5 | J7: 6 | K7: 7 | L7: 8 | M7: 9 | N7: 10
C9: Volume from own sources: | D9: Select this grading only if the water utility purchases/imports all of its water resources (i.e. has no sources of its own) | E9: Less than 25% of water production sources are metered, remaining sources are estimated. No regular meter accuracy testing. | F9: 25% - 50% of treated water production sources are metered; other sources estimated. No regular meter accuracy testing. | G9: Conditions between 2 and 4 | H9: 50% - 75% of treated water production sources are metered, other sources estimated. Occasional meter accuracy testing | I9: Conditions between 4 and 6 | J9: At least 75% of treated water production sources are metered, or at least 90% of the source flow is derived from metered sources. Meter accuracy testing and/or electronic calibration conducted annually. Less than 25% of tested meters are found outside of +/- 6% accuracy. | K9: Conditions between 6 and 8 | L9: 100% of treated water production sources are metered, meter accuracy testing and electronic calibration conducted annually, less than 10% of meters are found outside of +/- 6% accuracy | M9: Conditions between 8 and 10 | N9: 100% of treated water production sources are metered, meter accuracy testing and electronic calibration conducted semi-annually, with less than 10% found outside of +/- 3% accuracy. | Q9: ='Reporting Worksheet'!E14 -> 7 | R9: =IF(OR(C9=$R$3,C9=$R$4,C9=$R$5),1,0) -> 1
C10: Improvements to attain higher data grading for "Volume from own Sources" component: | E10: to qualify for 2: Organize efforts to begin to collect data for determining volume from own sources | F10: to qualify for 4: Locate all water production sources on maps and in field, launch meter accuracy testing for existing meters, begin to install meters on unmetered water production sources and replace any obsolete/defective meters | H10: to qualify for 6: Formalize annual meter accuracy testing for all source meters. Complete installation of meters on unmetered water production sources and complete replacement of all obsolete/defective meters. | J10: to qualify for 8: Conduct annual meter accuracy testing on all meters. Complete project to install new, or replace defective existing, meters so that entire production meter population is metered. Repair or replace meters outside of +/- 6% accuracy. | L10: to qualify for 10: Maintain annual meter accuracy testing for all meters. Repair or replace meters outside of +/- 6% accuracy. Investigate new meter technology; pilot one or more replacements with innovative meters in attempt to improve meter accuracy. | N10: to maintain 10: Standardize meter accuracy test frequency to semi-annual, or more frequent, for all meters. Repair or replace meters outside of +/- 3% accuracy. Continually investigate/pilot improving metering technology. | Q10: =Q9 -> 7
C11: Master meter error adjustment: | D11: Select n/a only if the water utility fails to have meters on its sources of supply, either its own source, and/or imported (purchased) water sources | E11: Inventory information on meters and paper records of measured volumes in crude condition; data error cannot be determined | F11: No automatic datalogging of production volumes; daily readings are scribed on paper records. Tank/storage elevation changes are not employed in calculating "Volume from own sources" component. Data is adjusted only when grossly evident data error occurs. | G11: Conditions between 2 and 4 | H11: Production meter data is logged automatically in electronic format and reviewed at least on a monthly basis. "Volume from own sources" tabulations include estimate of daily changes in tanks/storage facilities. Meter data is adjusted when gross data errors occur, or occasional meter testing deems this necessary. | I11: Conditions between 4 and 6 | J11: Hourly production meter data logged automatically & reviewed on at least a weekly basis. Data adjusted to correct gross error from equipment malfunction and error confirmed by meter accuracy testing. Tank/storage facility elevation changes are automatically used in calculating a balanced "Volume from own sources" component. | K11: Conditions between 6 and 8 | L11: Continuous production meter data logged automatically & reviewed daily. Data adjusted to correct gross error from equipment malfunction & results of meter accuracy testing. Tank/storage facility elevation changes are automatically used in "Volume from own sources" tabulations. | M11: Conditions between 8 and 10 | N11: Computerized system (SCADA or similar) automatically balances flows from all sources and storages; results reviewed daily. Mass balance technique compares production meter data to raw (untreated) water and treatment volumes to detect anomalies. Regular calibrations between SCADA and sources meters ensures minimal data transfer error. | Q11: ='Reporting Worksheet'!E15 -> 1 | R11: =IF(OR(C11=$R$3,C11=$R$4,C11=$R$5),1,0) -> 0
C12: Improvements to attain higher data grading for "Master meter error adjustment" component: | E12: to qualify for 2: Develop plan to restructure recordkeeping system to capture all flow data; set procedure to review data daily to detect input errors | F12: to qualify for 4: Install automatic datalogging equipment on production meters. Identify tanks/storage facilities and include estimated daily volume of water added to, or subtracted from, "Water Supplied" volume based upon changes in storage | H12: to qualify for 6: Review hourly production meter data for gross error on, at least, a weekly basis. Begin to install instrumentation on tanks/storage facilities to record elevation changes. Use daily net storage change to balance flows in calculating "Water Supplied" volume. | J12: to qualify for 8: Complete installation of elevation instrumentation on all tanks/storage facilities. Continue to use daily net storage change in calculating balanced "Volume from own sources" component. Adjust production meter data for gross error and inaccuracy confirmed by testing. | L12: to qualify for 10: Link all production and tank/storage facility elevation change data to a Supervisory Control & Data Acquisition (SCADA) System, or similar computerized monitoring/control system, and establish automatic flow balancing algorithm and regularly calibrate between SCADA and source meters. | N12: to maintain 10: Monitor meter innovations for development of more accurate and less expensive flowmeters. Continue to replace or repair meters as they perform outside of desired accuracy limits. | Q12: =Q11 -> 1
C13: Water Imported: | D13: Select n/a if the water utility's supply is exclusively from its own water resources (no bulk purchased/ imported water) | E13: Less than 25% of imported water sources are metered, remaining sources are estimated. No regular meter accuracy testing. | F13: 25% - 50% of imported water sources are metered; other sources estimated. No regular meter accuracy testing. | G13: Conditions between 2 and 4 | H13: 50% - 75% of imported water sources are metered, other sources estimated. Occasional meter accuracy testing | I13: Conditions between 4 and 6 | J13: At least 75% of imported water sources are metered, meter accuracy testing and/or electronic calibration conducted annually. Less than 25% of tested meters are found outside of +/- 6% accuracy. | K13: Conditions between 6 and 8 | L13: 100% of imported water sources are metered, meter accuracy testing and/or electronic calibration conducted annually, less than 10% of meters are found outside of +/- 6% accuracy | M13: Conditions between 8 and 10 | N13: 100% of imported water sources are metered, meter accuracy testing and/or electronic calibration conducted semi-annually, with less than 10% found outside of +/- 3% accuracy. | Q13: ='Reporting Worksheet'!E16 -> n/a | R13: =IF(OR(C13=$R$3,C13=$R$4,C13=$R$5),1,0) -> 0
C14: Improvements to attain higher data grading for "Water Imported Volume" component: | E14: to qualify for 2: Review bulk water purchase agreements with partner suppliers; confirm requirements for use and maintenance of accurate metering. Identify needs for new or replacement meters with goal to meter all imported water sources. | F14: To qualify for 4: Locate all imported water sources on maps and in field, launch meter accuracy testing for existing meters, begin to install meters on unmetered imported water interconnections and replace obsolete/defective meters | H14: to qualify for 6: Formalize annual meter accuracy testing for all imported water meters. Continue installation of meters on unmetered exported water interconnections and replacement of obsolete/defective meters. | J14: to qualify for 8: Complete project to install new, or replace defective, meters on all imported water interconnections. Maintain annual meter accuracy testing for all imported water meters. Repair or replace meters outside of +/- 6% accuracy. | L14: to qualify for 10: Maintain annual meter accuracy testing for all meters. Repair or replace meters outside of +/- 6% accuracy. Investigate new meter technology; pilot one or more replacements with innovative meters in attempt to improve meter accuracy. | N14: to maintain 10: Standardize meter accuracy test frequency to semi-annual, or more frequent, for all meters. Repair or replace meters outside of +/- 3% accuracy. Continually investigate/pilot improving metering technology. | Q14: =Q13 -> n/a
C15: Water Exported: | D15: Select n/a if the water utility sells no bulk water to neighboring water utilities (no exported water sales) | E15: Less than 25% of exported water sources are metered, remaining sources are estimated. No regular meter accuracy testing. | F15: 25% - 50% of exported water sources are metered; other sources estimated. No regular meter accuracy testing. | G15: Conditions between 2 and 4 | H15: 50% - 75% of exported water sources are metered, other sources estimated. Occasional meter accuracy testing | I15: Conditions between 4 and 6 | J15: At least 75% of exported water sources are metered, meter accuracy testing and/or electronic calibration conducted annually. Less than 25% of tested meters are found outside of +/- 6% accuracy. | K15: Conditions between 6 and 8 | L15: 100% of exported water sources are metered, meter accuracy testing and/or electronic calibration conducted annually, less than 10% of meters are found outside of +/- 6% accuracy | M15: Conditions between 8 and 10 | N15: 100% of exported water sources are metered, meter accuracy testing and/or electronic calibration conducted semi-annually, with less than 10% found outside of +/- 3% accuracy. | Q15: ='Reporting Worksheet'!E17 -> n/a | R15: =IF(OR(C15=$R$3,C15=$R$4,C15=$R$5),1,0) -> 0
C16: Improvements to attain higher data grading for "Water Exported Volume" component: | E16: to qualify for 2: Review bulk water sales agreements with partner suppliers; confirm requirements for use & upkeep of accurate metering. Identify needs to install new, or replace defective meters as needed. | F16: To qualify for 4: Locate all exported water sources on maps and in field, launch meter accuracy testing for existing meters, begin to install meters on unmetered exported water interconnections and replace obsolete/defective meters | H16: to qualify for 6: Formalize annual meter accuracy testing for all exported water meters. Continue installation of meters on unmetered exported water interconnections and replacement of obsolete/defective meters. | J16: to qualify for 8: Complete project to install new, or replace defective, meters on all exported water interconnections. Maintain annual meter accuracy testing for all imported water meters. Repair or replace meters outside of +/- 6% accuracy. | L16: to qualify for 10: Maintain annual meter accuracy testing for all meters. Repair or replace meters outside of +/- 6% accuracy. Investigate new meter technology; pilot one or more replacements with innovative meters in attempt to improve meter accuracy. | N16: to maintain 10: Standardize meter accuracy test frequency to semi-annual, or more frequent, for all meters. Repair or replace meters outside of +/- 3% accuracy. Continually investigate/pilot improving metering technology. | Q16: =Q15 -> n/a
C17: AUTHORIZED CONSUMPTION
C18: Billed metered: | D18: n/a (not applicable). Select n/a only if the entire customer population is not metered and is billed for water service on a flat or fixed rate basis. In such a case the volume entered must be zero. | E18: Less than 50% of customers with volume-based billings from meter readings; flat or fixed rate billed for the majority of the customer population | F18: At least 50% of customers with volume-based billing from meter reads; flat rate billed for others. Manual meter reading, under 50% read success rate, remainder estimated. Limited meter records, no regular meter testing or replacement. Billing data maintained on paper records, with no auditing. | G18: Conditions between 2 and 4 | H18: At least 75% of customers with volume-based billing from meter reads; flat or fixed rate billed for remainder. Manual meter reading used, at least 50% meter read success rate, failed reads are estimated. Purchase records verify age of customer meters; only very limited meter accuracy testing is conducted. Customer meters replaced only upon complete failure. Computerized billing records, but only periodic internal auditing conducted. | I18: Conditions between 4 and 6 | J18: At least 90% of customers with volume-based billing from meter reads; remaining accounts are estimated. Manual customer meter reading gives at least 80% customer meter reading success rate, failed reads are estimated. Good customer meter records, limited meter accuracy testing, regular replacement of oldest meters. Computerized billing records with routine auditing of global statistics. | K18: Conditions between 6 and 8 | L18: At least 97% of customers with volume-based billing from meter reads. At least 90% customer meter read success rate; or minimum 80% read success rate with planning and budgeting for trials of Automatic Metering Reading (AMR) in one or more pilot areas. Good customer meter records. Regular meter accuracy testing guides replacement of statistically significant number of meters each year. Routine auditing of computerized billing records for global and detailed statistics; verified periodically by third party. | M18: Conditions between 8 and 10 | N18: At least 99% of customers with volume-based billing from meter reads. At least 95% customer meter reading success rate; or minimum 80% meter reading success rate, with Automatic Meter Reading (AMR) trials underway. Statistically significant customer meter testing and replacement program in place. Computerized billing with routine, detailed auditing, including field investigation of representative sample of accounts. Annual audit verification by third party. | Q18: ='Reporting Worksheet'!E23 -> 6 | R18: =IF(OR(C18=$R$3,C18=$R$4,C18=$R$5),1,0) -> 1
C19: Improvements to attain higher data grading for "Billed Metered Consumption" component: | D19: If n/a is selected because the customer meter population is unmetered, consider establishing a new policy to meter the customer population and employ water rates based upon metered volumes. | E19: to qualify for 2: Conduct investigations or trials of customer meters to select appropriate meter models. Budget funding for meter installations. Investigate volume based water rate structures. | F19: to qualify for 4: Purchase and install meters on unmetered accounts. Implement policies to improve meter reading success. Catalog meter information during meter read visits to identify age/model of existing meters. Test a minimal number of meters for accuracy. Install computerized billing system. | H19: to qualify for 6: Purchase and install meters on unmetered accounts. Eliminate flat fee billing and establish appropriate water rate structure based upon measured consumption. Continue to achieve verifiable success in removing manual meter reading barriers. Expand meter accuracy testing. Launch regular meter replacement program. Conduct routine audit of global statistics. | J19: to qualify for 8: Purchase and install meters on unmetered accounts. Assess cost-effectiveness of Automatic Meter Reading (AMR) system for portion or entire system; or achieve ongoing improvements in manual meter reading success rate. Refine meter accuracy testing program. Set meter replacement goals based upon accuracy test results. Refine routine auditing procedures based upon third party guidance. | L19: to qualify for 10: Purchase and install meters on unmetered accounts. Launch Automatic Meter Reading (AMR) system trials if manual meter reading success rate of at least 95% is not achieved within a five-year program. Continue meter accuracy testing program. Conduct planning and budgeting for large scale meter replacement based upon meter life cycle analysis using cumulative flow target. Continue routine auditing and require annual third party review. | N19: to maintain 10: Regular internal and third party auditing, and meter accuracy testing ensures that accurate customer meter readings are obtained and entered as the basis for volume based billing. Stay abreast of improvements in Advanced Metering Infrastructure (AMI) and information management. Plan and budget for justified upgrades in metering, meter reading and billing data management. | Q19: =Q18 -> 6
C20: Billed unmetered: | D20: Select n/a if it is the policy of the water utility to meter all customer connections and it has been confirmed by detailed auditing that all customers do indeed have a water meter; i.e. no unmetered accounts exist | E20: Water utility policy does not require customer metering; flat or fixed fee billed. No data collected on customer consumption. Only estimates available are derived from data estimation methods using average fixture count multiplied by number of connections, or similar approach. | F20: Water utility policy does not require customer metering; flat or fixed fee billed. Some metered accounts exist in parts of the system (pilot areas or District Metered Areas) with consumption recorded on portable dataloggers. Data from these sample meters are used to infer consumption for the total customer population. Site specific estimation methods are used for unusual buildings/water uses. | G20: Conditions between 2 and 4 | H20: Water utility policy does require metering and volume based billing but lacks written procedures and employs casual oversight, resulting in up to 20% of billed accounts believed to be unmetered. A rough estimate of the annual consumption for all unmetered accounts is included in the annual water audit, with no inspection of individual unmetered accounts. | I20: Conditions between 4 and 6 | J20: Water utility policy does require metering and volume based billing but exemption exist for a portion of accounts such as municipal buildings. As many as 15% of billed accounts are unmetered due to this exemption or meter installation difficulties. Only a group estimate of annual consumption for all unmetered accounts is included in the annual water audit, with no inspection of individual unmetered accounts. | K20: Conditions between 6 and 8 | L20: Water utility policy requires metering and volume based billing for all customer accounts. However, less than 5% of billed accounts remain unmetered because because installation is hindered by unusual circumstances. The goal is to minimize the number of unmetered accounts. Reliable estimates of consumption are obtained for unmetered accounts via site specific estimation methods. | M20: Conditions between 8 and 10 | N20: Water utility policy requires metering and volume based billing for all customer accounts. Less than 2% of billed accounts are unmetered and exist because meter installation is hindered by unusual circumstances. The goal exists to minimize the number of unmetered accounts to the extent that is economical. Reliable estimates of consumption are obtained at these accounts via site specific estimation methods. | Q20: ='Reporting Worksheet'!E24 -> n/a | R20: =IF(OR(C20=$R$3,C20=$R$4,C20=$R$5),1,0) -> 0
C21: Improvements to attain higher data grading for "Billed Unmetered Consumption" component: | E21: to qualify for 2: Investigate a new water utility policy to require metering of the customer population, and a reduction of unmetered accounts. Conduct pilot metering project by installing water meters in small sample of customer accounts and datalogging the water consumption. | F21: to qualify for 4: Implement a new water utility policy requiring customer metering. Expand pilot metering study to include several different meter types, which will provide data for economic assessment of full scale metering options. Assess sites with access difficulties to devise means to obtain water consumption volumes. | H21: to qualify for 6: Budget for staff resources to review billing records to identify unmetered properties. Specify metering needs and funding requirements to install sufficient meters to significant reduce the number of unmetered accounts | J21: to qualify for 8: Install customer meters on a full scale basis. Refine metering policy and procedures to ensure that all accounts, including municipal properties, are designated for meters. Implement procedures to obtain reliable consumption estimate for unmetered accounts awaiting meter installation. | L21: to qualify for 10: Continue customer meter installation throughout the service area, with a goal to minimize unmetered accounts. Sustain the effort to investigate accounts with access difficulties to devise means to install water meters or otherwise measure water consumption. | N21: to maintain 10: Continue to refine estimation methods for unmetered consumption and explore means to establish metering, for as many billed unmetered accounts as is economically feasible. | Q21: =Q20 -> n/a
C22: Unbilled metered: | D22: select n/a if all billing-exempt consumption is unmetered. | E22: Billing practices exempt certain accounts, such as municipal buildings, but written policies do not exist; and a reliable count of unbilled metered accounts is unavailable. Meter upkeep and meter reading on these accounts is rare and not considered a priority. Due to poor recordkeeping and lack of auditing, water consumption for all such accounts is purely guesstimated. | F22: Billing practices exempt certain accounts, such as municipal buildings, but only scattered, dated written directives exist to justify this practice. A reliable count of unbilled metered accounts is unavailable. Sporadic meter replacement and meter reading occurs on an as-needed basis. The total annual water consumption for all unbilled, metered accounts is estimated based upon approximating the number of accounts and assigning consumption from actively billed accounts of same meter size. | G22: Conditions between 2 and 4 | H22: Dated written procedures permit billing exemption for specific accounts, such as municipal properties, but are unclear regarding certain other types of accounts. Meter reading is given low priority and is sporadic. Consumption is quantified from meter readings where available. The total number of unbilled, unmetered accounts must be estimated along with consumption volumes. | I22: Conditions between 4 and 6 | J22: Written policies regarding billing exemptions exist but adherence in practice is questionable. Metering and meter reading for municipal buildings is reliable but sporadic for other unbilled metered accounts. Periodic auditing of such accounts is conducted. Water consumption is quantified directly from meter readings where available, but the majority of the consumption is estimated. | K22: Conditions between 6 and 8 | L22: Written policy identifies the types of accounts granted a billing exemption. Customer meter management and meter reading are considered secondary priorities, but meter reading is conducted at least annually to obtain consumption volumes for the annual water audit. High level auditing of billing records ensures that a reliable census of such accounts exists. | M22: Conditions between 8 and 10 | N22: Clearly written policy identifies the types of accounts given a billing exemption, with emphasis on keeping such accounts to a minimum. Customer meter management and meter reading for these accounts is given proper priority and is reliably conducted. Regular auditing confirms this. Total water consumption for these accounts is taken from reliable readings from accurate meters. | Q22: ='Reporting Worksheet'!E25 -> 9 | R22: =IF(OR(C22=$R$3,C22=$R$4,C22=$R$5),1,0) -> 0
C23: Improvements to attain higher data grading for "Unbilled metered Consumption" component: | E23: to qualify for 2: Reassess the water utility's policy allowing certain accounts to be granted a billing exemption. Draft an outline of a new written policy for billing exemptions, with clear justification as to why any accounts should be exempt from billing, and with the intention to keep the number of such accounts to a minimum. | F23: to qualify for 4: Review historic written directives and policy documents allowing certain accounts to be billing-exempt. Draft an outline of a written policy for billing exemptions, identify criteria that grants an exemption, with a goal of keeping this number of accounts to a minimum. | H23: to qualify for 6: Draft a new written policy regarding billing exemptions based upon consensus criteria allowing this occurrence. Assign resources to audit meter records and billing records to obtain census of unbilled metered accounts. | J23: to qualify for 8: Communicate billing exemption policy throughout the organization and implement procedures that ensure proper account management. Conduct inspections of accounts confirmed in unbilled metered status and verify that accurate meters exist and are scheduled for routine meter readings. | L23: to qualify for 10: Ensure that meter management (meter accuracy testing, meter replacement) and meter reading activities are accorded the same priority as billed accounts. Establish ongoing annual auditing process to ensure that water consumption is reliably collected and provided to the annual water audit process. | N23: to maintain 10: Reassess philosophy in allowing any water uses to go "unbilled". It is possible to meter and bill all accounts, even if the fee charged for water consumption is discounted or waived. Metering and billing all accounts ensures that water consumption is tracked and water waste from plumbing leaks is detected and minimized. | Q23: =Q22 -> 9
C24: Unbilled unmetered: | E24: Extent of unbilled, unmetered consumption is unknown due to unclear policies and poor recordkeeping. Total consumption is quantified based upon a purely subjective estimate. | F24: Clear extent of unbilled, unmetered consumption is unknown, but a number of events are randomly documented each year, confirming existence of such consumption, but without sufficient documentation to quantify an accurate estimate of the annual volume consumed. | G24: Conditions between 2 and 4 | H24: Extent of unbilled, unmetered consumption is partially known, and procedures exist to document certain events such as miscellaneous fire hydrant uses. Formulae is used to quantify the consumption from such events (time running x typical flowrate x number of events). | I24: Default value of 1.25% of system input volume is employed | J24: Coherent policies exist for some forms of unbilled, unmetered consumption but others await closer evaluation. Reasonable recordkeeping for the managed uses exists and allows for annual volumes to be quantified by inference, but unsupervised uses are guesstimated. | K24: Conditions between 6 and 8 | L24: Clear policies and good recordkeeping exist for some uses (ex: unmetered fire connections registering consumption), but other uses (ex: miscellaneous uses of fire hydrants) have limited oversight. Total consumption is a mix of well quantified use such as from formulae (time x typical flow) or temporary meters, and relatively subjective estimates of less regulated use. | M24: Conditions between 8 and 10 | N24: Clear policies exist to identify permitted use of water in unbilled, unmetered fashion, with the intention of minimizing this type of consumption. Good records document each occurrence and consumption is quantified via formulae (time x typical flow) or use of temporary meters. | Q24: ='Reporting Worksheet'!E26 -> 0 | R24: =IF(OR(C24=$R$3,C24=$R$4,C24=$R$5),1,0) -> 0
C25: Improvements to attain higher data grading for "Unbilled Unmetered Consumption" component: | E25: to qualify for 5: Utilize accepted default value of 1.25% of system input volume as an expedient means to gain a reasonable quantification of this use. to qualify for 2: Establish a policy regarding what water uses should be allowed as unbilled and unmetered. Consider tracking a small sample of one such use (ex: fire hydrant flushings). | F25: to qualify for 5: Utilize accepted default value of 1.25% of system input volume as an expedient means to gain a reasonable quantification of this use. to qualify for 4: Evaluate the documentation of events that have been observed. Meet with user groups (ex: for fire hydrants - fire departments, contractors to ascertain their need for water from fire hydrants). | H25: to qualify for 5: Utilize accepted default value of 1.25% of system input volume as expedient means to gain a reasonable quantification of all such use. This is particularly appropriate for water utilities who are in the early stages of the water auditing process. | I25: to qualify for 6 or greater: Finalize policy and do field checks. Proceed if top-down audit exists and/or a great volume of such use is suspected. | J25: to qualify for 8: Assess water utility policy and procedures to ensure that fire hydrant permits are issued for use by persons outside of the utility. Create written procedures for use and documentation of fire hydrants by water utility personnel. | L25: to qualify for 10: Refine written procedures to ensure that all uses of unbilled, unmetered water are overseen by a structured permitting process managed by water utility personnel. Reassess policy to determine if some of these uses have value in being converted to billed and/or metered status. | N25: to maintain 10: Continue to refine policy and procedures with intention of reducing the number of allowable uses of water in unbilled and unmetered fashion. Any uses that can feasibly become billed and metered should be converted eventually. | Q25: =Q24 -> 0
C26: APPARENT LOSSES
C27: Unauthorized consumption: | E27: Extent of unauthorized consumption is unknown due to unclear policies and poor recordkeeping. Total unauthorized consumption is guesstimated. | F27: Unauthorized consumption is a known occurrence, but its extent is a mystery. There are no requirements to document observed events, but periodic field reports capture some of these occurrences. Total unauthorized consumption is approximated from this limited data. | G27: conditions between 2 and 4 | H27: Procedures exist to document some unauthorized consumption such as observed unauthorized fire hydrant openings. Use formulae to quantify this consumption (time running x typical flowrate x number of events). | I27: Default value of 0.25% of system input volume is employed | J27: Coherent policies exist for some forms of unauthorized consumption but others await closer evaluation. Reasonable surveillance and recordkeeping exist for occurrences that fall under the policy. Volumes quantified by inference from these records. Unsupervised uses are guesstimated. | K27: Conditions between 6 and 8 | L27: Clear policies and good recordkeeping exist for certain events (ex: tampering with water meters); other occurrences have limited oversight. Total consumption is a combination of volumes from formulae (time x typical flow) and subjective estimates of unconfirmed consumption. | M27: Conditions between 8 and 10 | N27: Clear policies exist to identify all known unauthorized uses of water. Staff and procedures exist to provide enforcement of policies and detect violations. Each occurrence is quantified via formulae (time x typical flow) or similar methods. | Q27: ='Reporting Worksheet'!E38 -> 0 | R27: =IF(OR(C27=$R$3,C27=$R$4,C27=$R$5),1,0) -> 0
C28: Improvements to attain higher data grading for "Unauthorized Consumption" component: | E28: to qualify for 5: Use accepted default of 0.25% of system input volume. to qualify for 2: Review utility policy regarding what water uses are considered unauthorized, and consider tracking a small sample of one such occurrence (ex: unauthorized fire hydrant openings) | F28: to qualify for 5: Use accepted default of 0.25% of system input volume to qualify for 4: Review utility policy regarding what water uses are considered unauthorized, and consider tracking a small sample of one such occurrence (ex: unauthorized fire hydrant openings) | H28: to qualify for 5: Utilize accepted default value of 0.25% of system input volume as expedient means to gain a reasonable quantification of all such use. This is particularly appropriate for water utilities who are in the early stages of the water auditing process. | I28: to qualify for 6 or greater: Finalize policy and do field checks. Proceed if top-down audit exists and/or a great volume of such use is suspected. | J28: to quality for 8: Assess water utility policies to ensure that all known occurrences of unauthorized consumption are outlawed, and that appropriate penalties are prescribed. Create written procedures for use and documentation of various occurrences of unauthorized consumption as they are uncovered. | L28: to qualify for 10: Refine written procedures and assign staff to seek out likely occurrences of unauthorized consumption. Explore new locking devices, monitors and other technologies designed to detect and thwart unauthorized consumption. | N28: to maintain 10: Continue to refine policy and procedures to eliminate any loopholes that allow or tacitly encourage unauthorized consumption. Continue to be vigilant in documentation and enforcement efforts. | Q28: =Q27 -> 0
C29: Customer metering inaccuracies: | D29: select n/a only if the entire customer population is unmetered. In such a case the volume entered must be zero. | E29: Customer meters exist, but with unorganized paper records on meters; no meter accuracy testing or meter replacement program. Workflow is driven chaotically by customer complaints with no proactive management. Loss volume due to aggregate meter inaccuracy is guesstimated. | F29: Poor recordkeeping and meter oversight is recognized by water utility management who has allotted staff and funding resources to organize improved recordkeeping and start meter accuracy testing. Existing paper records gathered and organized to provide cursory disposition of meter population. | G29: Conditions between 2 and 4 | H29: Reliable recordkeeping exists; meter information is improving as meters are replaced. Meter accuracy testing is conducted annually for a small number of meters. Limited number of oldest meters replaced each year. Inaccuracy volume is largely an estimate, but refined based upon limited testing data. | I29: Conditions between 4 and 6 | J29: A reliable electronic recordkeeping system for meters exists. Population includes a mix of new high performing meters and dated meters with suspect accuracy. Routine, but limited, meter accuracy testing and meter replacement occur. Inaccuracy volume is quantified using a mix of reliable and less certain data. | K29: Conditions between 6 and 8 | L29: Ongoing meter replacement and accuracy testing result in highly accurate customer meter population. Testing is conducted on samples of meters at varying lifespans to determine optimum replacement time for various types of meters. | M29: Conditions between 8 and 10 | N29: Good records of number, type and size of customer meters; ongoing meter replacement occurs. Regular meter accuracy testing gives reliable measure of composite inaccuracy volume for the system. New metering technology is embraced to keep overall accuracy improving. | Q29: ='Reporting Worksheet'!E42 -> 3 | R29: =IF(OR(C29=$R$3,C29=$R$4,C29=$R$5),1,0) -> 1
