Workbook

Sheet Instructions
A1: 4.2
B2: AWWA Free Water Audit Software v5.0
U3: Select a state / province from the list
C4: This spreadsheet-based water audit tool is designed to help quantify and track water losses associated with water distribution systems and identify areas for improved efficiency and cost recovery. It provides a "top-down" summary water audit format, and is not meant to take the place of a full-scale, comprehensive water audit format. | U4: Alaska (AK)
U5: Alabama (AL)
C6: Auditors are strongly encouraged to refer to the most current edition of AWWA M36 Manual for Water Audits for detailed guidance on the water auditing process and targetting loss reduction levels | U6: Arkansas (AR)
C7: The spreadsheet contains several separate worksheets. Sheets can be accessed using the tabs towards the bottom of the screen, or by clicking the buttons below. | U7: Arizona (AZ)
U8: California (CA)
U9: Colorado (CO)
C10: Please begin by providing the following information | J10: The following guidance will help you complete the Audit | U10: Connecticut (CT)
U11: Dist. Columbia (DC)
C12: Name of Contact Person: | D12: Eric Storms | J12: All audit data are entered on the | M12: Reporting Worksheet | U12: Delaware (DE)
U13: Florida (FL)
C14: Email Address: | D14: eric.storms@suez.com | L14: Value can be entered by user | U14: Georgia (GA)
U15: Hawaii (HI)
C16: Telephone | Ext.: | D16: 302-252-3032 | L16: Value calculated based on input data | U16: Iowa (IA)
U17: Idaho (ID)
C18: Name of City / Utility: | D18: Suez Water DE | L18: These cells contain recommended default values | U18: Illinois (IL)
U19: Indiana (IN)
C20: City/Town/Municipality: | D20: Wilmington | U20: Kansas (KS)
U21: Kentucky (KY)
C22: State / Province: | D22: Delaware (DE) | J22: Use of Option (Radio) Buttons: | L22: Pcnt: | N22: Value: | U22: Louisiana (LA)
U23: Massachusetts (MA)
C24: Country: | D24: New Castle | L24: 0.0025 | U24: Maryland (MD)
U25: Maine (ME)
C26: Year: | D26: 2020 | E26: Calendar Year | U26: Michigan (MI)
U27: Minnesota (MN)
C28: Start Date: | E28: Enter MM/YYYY numeric format | U28: Missouri (MO)
U29: Mississippi (MS)
C30: End Date: | E30: Enter MM/YYYY numeric format | U30: Montana (MT)
U31: Nebraska (NE)
C32: Audit Preparation Date: | D32: 44202 | U32: Nevada (NV)
U33: New Hampshire (NH)
C34: Volume Reporting Units: | D34: Million gallons (US) | U34: New Jersey (NJ)
U35: New Mexico (NM)
C36: PWSID / Other ID: | U36: New York (NY)
D37: The following worksheets are available by clicking the buttons below or selecting the tabs along the bottom of the page | U37: North Carolina (NC)
U38: North Dakota (ND)
U39: Ohio (OH)
U40: Oklahoma (OK)
...

Sheet Reporting Worksheet
B2: AWWA Free Water Audit Software: Reporting Worksheet
C4: Water Audit Report for: | D4: =IF(ISBLANK(Instructions!D18),"<< Please enter system details and contact information on the Instructions tab >>",Instructions!D18&IF(ISBLANK(Instructions!D36),""," ("&Instructions!D36&")")) -> Suez Water DE
C5: Reporting Year: | D5: =IF(ISBLANK(Instructions!D26),"",Instructions!D26) -> 2020 | G5: =IF(ISBLANK(Instructions!D26),"",IF(Instructions!E26="Calendar Year","1/"&Instructions!D26&" - "&"12/"&Instructions!D26,IF(OR(ISBLANK(Instructions!D28),ISBLANK(Instructions!D30)),"",MONTH(Instructions!D28)&"/"&YEAR(Instructions!D28)&" - "&MONTH(Instructions!D30)&"/"&YEAR(Instructions!D30)))) -> 1/2020 - 12/2020
G9: =IF(ISBLANK(Instructions!D34),"PLEASE CHOOSE REPORTING UNITS FROM THE INSTRUCTIONS SHEET BEFORE ENTERING DATA","All volumes to be entered as: "&UPPER(Instructions!$D$34)&" PER YEAR") -> All volumes to be entered as: MILLION GALLONS (US) PER YEAR
J12: Master Meter and Supply Error Adjustments
C13: WATER SUPPLIED | D13: <----------- Enter grading in column 'E' and 'J' ----------> | L13: Pcnt: | N13: Value: | R13: Pcnt(1) or Val(2) | T13: Raw Vol | U13: MME | W13: Grading weighting points in red
C15: Volume from own sources: | E15: 7 | G15: 5243.759 | I15: =IF(Instructions!$D$34="million gallons (US)","MG/Yr",IF(Instructions!$D$34="Megalitres (thousand cubic metres)","ML/Yr",IF(Instructions!$D$34="acre-feet","acre-ft/yr",""))) -> MG/Yr | P15: =IF(Instructions!$D$34="million gallons (US)","MG/Yr",IF(Instructions!$D$34="Megalitres (thousand cubic metres)","ML/Yr",IF(Instructions!$D$34="acre-feet","acre-ft/yr",""))) -> MG/Yr | R15: 1 | S15: =IF(G15>0,IF(R15=1,L15*G15,N15),0) -> 0 | T15: =$T$19/$T$18*G15 -> 33.177901 | U15: =$T$19/$T$18*ABS(S15) -> 0
C16: Water imported: | E16: 9 | G16: 233.6473 | I16: =IF(Instructions!$D$34="million gallons (US)","MG/Yr",IF(Instructions!$D$34="Megalitres (thousand cubic metres)","ML/Yr",IF(Instructions!$D$34="acre-feet","acre-ft/yr",""))) -> MG/Yr | P16: =IF(Instructions!$D$34="million gallons (US)","MG/Yr",IF(Instructions!$D$34="Megalitres (thousand cubic metres)","ML/Yr",IF(Instructions!$D$34="acre-feet","acre-ft/yr",""))) -> MG/Yr | R16: 1 | S16: =IF(G16>0,IF(R16=1,L16*G16,N16),0) -> 0 | T16: =$T$19/$T$18*G16 -> 1.4783149 | U16: =$T$19/$T$18*ABS(S16) -> 0
C17: Water exported: | E17: 2 | G17: 54.335 | I17: =IF(Instructions!$D$34="million gallons (US)","MG/Yr",IF(Instructions!$D$34="Megalitres (thousand cubic metres)","ML/Yr",IF(Instructions!$D$34="acre-feet","acre-ft/yr",""))) -> MG/Yr | P17: =IF(Instructions!$D$34="million gallons (US)","MG/Yr",IF(Instructions!$D$34="Megalitres (thousand cubic metres)","ML/Yr",IF(Instructions!$D$34="acre-feet","acre-ft/yr",""))) -> MG/Yr | R17: 1 | S17: =IF(G17>0,IF(R17=1,L17*G17,N17),0) -> 0 | T17: =$T$19/$T$18*G17 -> 0.34378415 | U17: =$T$19/$T$18*ABS(S17) -> 0
J18: Enter negative % or value for under-registration | T18: =G15+G16+G17+IF(G15>0,ABS(S15),0)+IF(G16>0,ABS(S16),0)+IF(G17>0,(ABS(S17)),) -> 5531.7413
C19: WATER SUPPLIED: | G19: =IF(G15>0,IF(R15=1,G15/(1+L15),G15-N15),0)+IF(G16>0,IF(R16=1,G16/(1+L16),G16-N16),0)-IF(G17>0,IF(R17=1,G17/(1+L17),G17-N17),0) -> 5423.0713 | I19: =IF(Instructions!$D$34="million gallons (US)","MG/Yr",IF(Instructions!$D$34="Megalitres (thousand cubic metres)","ML/Yr",IF(Instructions!$D$34="acre-feet","acre-ft/yr",""))) -> MG/Yr | J19: Enter positive % or value for over-registration | T19: =GradingAssessment!D27 -> 35 | U19: total weighting pts
E21: .
C22: AUTHORIZED CONSUMPTION
C23: Billed metered: | E23: 9 | G23: 4440.547 | I23: =IF(Instructions!$D$34="million gallons (US)","MG/Yr",IF(Instructions!$D$34="Megalitres (thousand cubic metres)","ML/Yr",IF(Instructions!$D$34="acre-feet","acre-ft/yr",""))) -> MG/Yr
C24: Billed unmetered: | E24: n/a | I24: =IF(Instructions!$D$34="million gallons (US)","MG/Yr",IF(Instructions!$D$34="Megalitres (thousand cubic metres)","ML/Yr",IF(Instructions!$D$34="acre-feet","acre-ft/yr",""))) -> MG/Yr
C25: Unbilled metered: | E25: 8 | G25: 53.98333 | I25: =IF(Instructions!$D$34="million gallons (US)","MG/Yr",IF(Instructions!$D$34="Megalitres (thousand cubic metres)","ML/Yr",IF(Instructions!$D$34="acre-feet","acre-ft/yr",""))) -> MG/Yr | L25: Pcnt: | N25: Value: | AA25: Testing... different object positioning settings to try to prevent radio buttons from moving - seeing this on many completed audits. Evaluate performance during beta testing
C26: Unbilled unmetered: | G26: =IF(OR(R26=1,AND(R26=2,N26=0)),L26*$G$19,N26) -> 67.788391 | I26: =IF(Instructions!$D$34="million gallons (US)","MG/Yr",IF(Instructions!$D$34="Megalitres (thousand cubic metres)","ML/Yr",IF(Instructions!$D$34="acre-feet","acre-ft/yr",""))) -> MG/Yr | L26: 0.0125 | P26: =IF(Instructions!$D$34="million gallons (US)","MG/Yr",IF(Instructions!$D$34="Megalitres (thousand cubic metres)","ML/Yr",IF(Instructions!$D$34="acre-feet","acre-ft/yr",""))) -> MG/Yr | R26: 1 | T26: Format Shape > Properties - Object positioning: Move and Size with cells
N27: 24061
C28: =IF(R26=1," Default option selected for Unbilled unmetered - a grading of 5 is applied but not displayed",IF(R26=2,IF(N26>0.0125*G19," Unbilled Unmetered volume entered is greater than the recommended default value",IF(N26=0,"Enter a positive value, otherwise a default percentage of 1.25% (of billed metered) is applied and a grading of 5 is applied but not displayed","")))) -> Default option selected for Unbilled unmetered - a grading of 5 is applied but not displayed
C30: AUTHORIZED CONSUMPTION: | G30: =SUM(G23:G26) -> 4562.3187 | I30: =IF(Instructions!$D$34="million gallons (US)","MG/Yr",IF(Instructions!$D$34="Megalitres (thousand cubic metres)","ML/Yr",IF(Instructions!$D$34="acre-feet","acre-ft/yr",""))) -> MG/Yr
C32: =IF(AND(G30>=G19,(G30<>0))," Check input values; WATER SUPPLIED should be greater than AUTHORIZED CONSUMPTION","") | T32: look into locking radio buttons in place - they often seem to move
C35: WATER LOSSES (Water Supplied - Authorized Consumption) | G35: =G19-G30 -> 860.75258 | I35: =IF(Instructions!$D$34="million gallons (US)","MG/Yr",IF(Instructions!$D$34="Megalitres (thousand cubic metres)","ML/Yr",IF(Instructions!$D$34="acre-feet","acre-ft/yr",""))) -> MG/Yr
C37: Apparent Losses | L37: Pcnt: | N37: Value:
C38: Unauthorized consumption: | G38: =IF(OR(R38=1,AND(R38=2,N38=0)),L38*$G$19,N38) -> 13.557678 | I38: =IF(Instructions!$D$34="million gallons (US)","MG/Yr",IF(Instructions!$D$34="Megalitres (thousand cubic metres)","ML/Yr",IF(Instructions!$D$34="acre-feet","acre-ft/yr",""))) -> MG/Yr | L38: 0.0025 | P38: =IF(Instructions!$D$34="million gallons (US)","MG/Yr",IF(Instructions!$D$34="Megalitres (thousand cubic metres)","ML/Yr",IF(Instructions!$D$34="acre-feet","acre-ft/yr",""))) -> MG/Yr | R38: 1 | T38: Format Shape > Properties - Object positioning: Move but don't size with cells
C40: =IF(R38=1," Default option selected for unauthorized consumption - a grading of 5 is applied but not displayed ",IF(R38=2,IF(N38>0.0025*G19,"Unauthorized consumption volume entered is greater than the recommended default value",IF(N38=0,"Enter a positive value, otherwise a default percentage of 0.25% is applied and a grading of 5 is applied but not displayed","")))) -> Default option selected for unauthorized consumption - a grading of 5 is applied but not displayed
C42: Customer metering inaccuracies: | E42: 6 | G42: =IF(R42=1,((G23+G25)/(1-L42))-(G23+G25),N42) -> 0 | I42: =IF(Instructions!$D$34="million gallons (US)","MG/Yr",IF(Instructions!$D$34="Megalitres (thousand cubic metres)","ML/Yr",IF(Instructions!$D$34="acre-feet","acre-ft/yr",""))) -> MG/Yr | L42: 0 | P42: =IF(Instructions!$D$34="million gallons (US)","MG/Yr",IF(Instructions!$D$34="Megalitres (thousand cubic metres)","ML/Yr",IF(Instructions!$D$34="acre-feet","acre-ft/yr",""))) -> MG/Yr | R42: 1 | T42: Format Shape > Properties - Was forced to change this to: size with cells because of "Can't shift objects off sheet error"
C43: Systematic data handling errors: | G43: =IF(R43=1,L43*$G$23,N43) -> 11.101367 | I43: =IF(Instructions!$D$34="million gallons (US)","MG/Yr",IF(Instructions!$D$34="Megalitres (thousand cubic metres)","ML/Yr",IF(Instructions!$D$34="acre-feet","acre-ft/yr",""))) -> MG/Yr | L43: 0.0025 | P43: =IF(Instructions!$D$34="million gallons (US)","MG/Yr",IF(Instructions!$D$34="Megalitres (thousand cubic metres)","ML/Yr",IF(Instructions!$D$34="acre-feet","acre-ft/yr",""))) -> MG/Yr | R43: 1
C45: =IF(OR(G19=0,E43="n/a"),"",IF(OR(ISBLANK(G43),G43=0),"Systematic data handling errors are likely, please enter a positive, non-zero value; otherwise grade = 1 (not displayed)",IF(R43=1," Default option selected for Systematic data handling errors - a grading of 5 is applied but not displayed",""))) -> Default option selected for Systematic data handling errors - a grading of 5 is applied but not displayed
C47: Apparent Losses: | G47: =G38+G42+G43 -> 24.659046 | I47: =IF(Instructions!$D$34="million gallons (US)","MG/Yr",IF(Instructions!$D$34="Megalitres (thousand cubic metres)","ML/Yr",IF(Instructions!$D$34="acre-feet","acre-ft/yr",""))) -> MG/Yr
C49: =IF(AND(G47>=G35,(G47<>0)),"Check input values; APPARENT LOSSES should be less than WATER LOSSES","")
C51: Real Losses (Current Annual Real Losses or CARL)
C52: Real Losses = Water Losses - Apparent Losses: | G52: =G35-G47 -> 836.09353 | I52: =IF(Instructions!$D$34="million gallons (US)","MG/Yr",IF(Instructions!$D$34="Megalitres (thousand cubic metres)","ML/Yr",IF(Instructions!$D$34="acre-feet","acre-ft/yr",""))) -> MG/Yr
C54: WATER LOSSES: | G54: =G47+G52 -> 860.75258 | I54: =IF(Instructions!$D$34="million gallons (US)","MG/Yr",IF(Instructions!$D$34="Megalitres (thousand cubic metres)","ML/Yr",IF(Instructions!$D$34="acre-feet","acre-ft/yr",""))) -> MG/Yr
C57: NON-REVENUE WATER
C58: NON-REVENUE WATER: | G58: =G35+G25+G26 -> 982.5243 | I58: =IF(Instructions!$D$34="million gallons (US)","MG/Yr",IF(Instructions!$D$34="Megalitres (thousand cubic metres)","ML/Yr",IF(Instructions!$D$34="acre-feet","acre-ft/yr",""))) -> MG/Yr
C59: = Water Losses + Unbilled Metered + Unbilled Unmetered
C60: SYSTEM DATA
C62: Length of mains: | E62: 9 | G62: 551 | I62: =IF(ISBLANK(Instructions!$D$34),"",IF(Instructions!$D$34="Megalitres (thousand cubic metres)","kilometers","miles")) -> miles
C63: Number of active AND inactive service connections: | E63: 6 | G63: 40933
C64: Service connection density: | G64: =IF(ISERROR(G63/G62),"",G63/G62) -> 74.288566 | I64: =IF(ISBLANK(Instructions!$D$34),"",IF(Instructions!$D$34="Megalitres (thousand cubic metres)","conn./km","conn./mile")& " main") -> conn./mile main
...

Sheet Performance Indicators
A1: 0
B2: AWWA Free Water Audit Software: System Attributes and Performance Indicators
C4: Water Audit Report for: | D4: =IF(ISBLANK(Instructions!D18),"<< Please enter system details and contact information on the Instructions tab >>",Instructions!D18&IF(ISBLANK(Instructions!D36),""," ("&Instructions!D36&")")) -> Suez Water DE
C5: Reporting Year: | D5: =IF(ISBLANK(Instructions!D26),"",Instructions!D26) -> 2020 | G5: =IF(ISBLANK(Instructions!D26),"",IF(Instructions!E26="Calendar Year","1/"&Instructions!D26&" - "&"12/"&Instructions!D26,IF(OR(ISBLANK(Instructions!D28),ISBLANK(Instructions!D30)),"",MONTH(Instructions!D28)&"/"&YEAR(Instructions!D28)&" - "&MONTH(Instructions!D30)&"/"&YEAR(Instructions!D30)))) -> 1/2020 - 12/2020
C9: =IF(ISBLANK(Instructions!$D$34),"********** REPORTING UNITS MUST BE SELECTED ON THE INSTRUCTIONS WORKSHEET BEFORE PERFORMANCE INDICATORS CAN BE DISPLAYED **********",IF(GradingAssessment!M24>0," ********** DATA GRADING MUST BE COMPLTED ON THE REPORTING WORKSHEET BEFORE PERFORMANCE INDICATORS CAN BE DISPLAYED **********","*** YOUR WATER AUDIT DATA VALIDITY SCORE IS: "&ROUND(GradingAssessment!G24,0)&" out of 100 ***")) -> *** YOUR WATER AUDIT DATA VALIDITY SCORE IS: 70 out of 100 ***
C10: System Attributes:
G11: Apparent Losses: | I11: =IF(ISBLANK(Instructions!$D$34),"",'Reporting Worksheet'!G47) -> 24.659046 | J11: =IF(Instructions!$D$34="million gallons (US)","MG/Yr",IF(Instructions!$D$34="Megalitres (thousand cubic metres)","ML/Yr",IF(Instructions!$D$34="acre-feet","acre-ft/yr",""))) -> MG/Yr | R11: =GradingAssessment!M24 -> 0 | S11: >0 if a grading has been missed
G13: + Real Losses: | I13: =IF(ISBLANK(Instructions!$D$34),"",'Reporting Worksheet'!G52) -> 836.09353 | J13: =IF(Instructions!$D$34="million gallons (US)","MG/Yr",IF(Instructions!$D$34="Megalitres (thousand cubic metres)","ML/Yr",IF(Instructions!$D$34="acre-feet","acre-ft/yr",""))) -> MG/Yr | R13: =IF(ISBLANK(Instructions!$D$34),0,1) -> 1 | S13: =0 if no reporting units selected
G15: = Water Losses: | I15: =IF(ISBLANK(Instructions!$D$34),"",'Reporting Worksheet'!G54) -> 860.75258 | J15: =IF(Instructions!$D$34="million gallons (US)","MG/Yr",IF(Instructions!$D$34="Megalitres (thousand cubic metres)","ML/Yr",IF(Instructions!$D$34="acre-feet","acre-ft/yr",""))) -> MG/Yr
G17: Unavoidable Annual Real Losses (UARL): | I17: =IF(ISBLANK(Instructions!$D$34),"",IF(Instructions!$D$34="Megalitres (thousand cubic metres)",IF(AND('Reporting Worksheet'!G69>=25,'Reporting Worksheet'!G62*20+'Reporting Worksheet'!G63>3000),(((18*'Reporting Worksheet'!G62)+(0.8*'Reporting Worksheet'!G63)+(25*('Reporting Worksheet'!G63*'Reporting Worksheet'!R68/1000)))*'Reporting Worksheet'!G69/1000000)*365,"Not Valid"),IF(AND('Reporting Worksheet'!G69>=35,'Reporting Worksheet'!G62*32+'Reporting Worksheet'!G63>3000),(((5.41*'Reporting Worksheet'!G62)+(0.15*'Reporting Worksheet'!G63)+(7.5*('Reporting Worksheet'!G63*'Reporting Worksheet'!R68/5280)))*'Reporting Worksheet'!G69)/IF(Instructions!$D$34="Million gallons (US)",1000000,325851.427242)*365,"See limits in definition"))) -> 268.74518 | J17: =IF(Instructions!$D$34="million gallons (US)","MG/Yr",IF(Instructions!$D$34="Megalitres (thousand cubic metres)","ML/Yr",IF(Instructions!$D$34="acre-feet","acre-ft/yr",""))) -> MG/Yr
G19: Annual cost of Apparent Losses: | I19: =IF(OR(ISBLANK(Instructions!$D$34),ISBLANK('Reporting Worksheet'!I77)),"",('Reporting Worksheet'!G47*'Reporting Worksheet'!G77)*INDEX(Sheet1!B2:D4,MATCH(Instructions!D34,Sheet1!A2:A4,0),MATCH('Reporting Worksheet'!I77,Sheet1!B1:D1,0))) -> 136857.7
G21: Annual cost of Real Losses: | I21: =IF(ISBLANK(Instructions!D34),"",IF(ISBLANK('Reporting Worksheet'!G78),"",'Reporting Worksheet'!G52*(IF(R21=FALSE,'Reporting Worksheet'!G78,IF(R21=TRUE,'Reporting Worksheet'!G77*INDEX(Sheet1!B2:D4,MATCH(Instructions!D34,Sheet1!A2:A4,0),MATCH('Reporting Worksheet'!I77,Sheet1!B1:D1,0)),""))))) -> 4640319.1 | L21: Valued at | M21: =IF(R21=FALSE,"Variable Production Cost","Customer Retail Unit Cost") -> Customer Retail Unit Cost | R21: TRUE | S21: FALSE=VPC;TRUE=CRUC
J22: Return to Reporting Worksheet to change this assumption | S22: We could add a 3rd option - another box for $ input (at user defined rate)
C24: Performance Indicators:
G26: Non-revenue water as percent by volume of Water Supplied: | I26: =IF(ISERROR(1/'Reporting Worksheet'!G19),"",('Reporting Worksheet'!G25+'Reporting Worksheet'!G26+'Reporting Worksheet'!G47+'Reporting Worksheet'!G52)/'Reporting Worksheet'!G19) -> 0.18117488
G28: Non-revenue water as percent by cost of operating system: | I28: =IF(ISERROR(1/'Reporting Worksheet'!G76),"",((('Reporting Worksheet'!G25+'Reporting Worksheet'!G26+'Reporting Worksheet'!G52)*IF(R21=FALSE,'Reporting Worksheet'!G78,'Reporting Worksheet'!G77*INDEX(Sheet1!B2:D4,MATCH(Instructions!D34,Sheet1!A2:A4,0),MATCH('Reporting Worksheet'!I77,Sheet1!B1:D1,0))))+('Reporting Worksheet'!G47*'Reporting Worksheet'!G77*INDEX(Sheet1!B2:D4,MATCH(Instructions!D34,Sheet1!A2:A4,0),MATCH('Reporting Worksheet'!I77,Sheet1!B1:D1,0))))/'Reporting Worksheet'!G76) -> 0.26284682 | J28: =" Real Losses valued at "&IF(R21=FALSE,"Variable Production Cost","Customer Retail Unit Cost") -> Real Losses valued at Customer Retail Unit Cost
G32: Apparent Losses per service connection per day: | I32: =IF(ISERROR(1/'Reporting Worksheet'!G63),"",IF(Instructions!$D$34="Acre-feet",'Reporting Worksheet'!G47*325851/1000000,'Reporting Worksheet'!G47)*1000000/365/'Reporting Worksheet'!G63) -> 1.6504783 | J32: =IF(ISBLANK(Instructions!$D$34),"",IF(Instructions!$D$34="Megalitres (thousand cubic metres)","litres","gallons")&"/connection/day") -> gallons/connection/day
G34: Real Losses per service connection per day: | I34: =IF(ISERROR(1/'Reporting Worksheet'!G63),"",IF(Instructions!$D$34="Megalitres (thousand cubic metres)",IF('Reporting Worksheet'!G64>20,'Reporting Worksheet'!G52*1000000/365/'Reporting Worksheet'!G63,"N/A"),IF('Reporting Worksheet'!G64>32,IF(Instructions!$D$34="Million gallons (US)",'Reporting Worksheet'!G52*1000000,'Reporting Worksheet'!G52*325851)/365/'Reporting Worksheet'!G63,"N/A"))) -> 55.961381 | J34: =IF(ISBLANK(Instructions!$D$34),"",IF(Instructions!$D$34="Megalitres (thousand cubic metres)","litres","gallons")&"/connection/day") -> gallons/connection/day
G36: Real Losses per length of main per day*: | I36: =IF(ISERROR(1/'Reporting Worksheet'!G62),"",IF(I34="N/A",IF(Instructions!$D$34="Acre-feet",'Reporting Worksheet'!G52*325851/1000000,'Reporting Worksheet'!G52)*1000000/365/'Reporting Worksheet'!G62,"N/A")) -> N/A | J36: =IF(ISBLANK(Instructions!$D$34),"",IF(I36="N/A","",IF(Instructions!$D$34="Megalitres (thousand cubic metres)","litres/km","gallons/mile")&"/day"))
G38: ="Real Losses per service connection per day per "& IF('Reporting Worksheet'!I69="psi","psi pressure","meter (head) pressure")&":" -> Real Losses per service connection per day per psi pressure: | I38: =IF(I34="N/A","N/A",IF(ISERROR(I34/'Reporting Worksheet'!G69),"",I34/'Reporting Worksheet'!G69)) -> 0.84789971 | J38: =IF(ISBLANK(Instructions!$D$34),"",IF(Instructions!$D$34="Megalitres (thousand cubic metres)","litres/connection/day/m","gallons/connection/day/psi")) -> gallons/connection/day/psi
C41: =IF(I17="Not Valid","*** UARL cannot be calculated as either average pressure, number of connections or length of mains is too small: SEE UARL DEFINITION ***","")
G43: From Above, Real Losses = Current Annual Real Losses (CARL): | I43: =IF(ISBLANK(Instructions!$D$34),"",'Reporting Worksheet'!G52) -> 836.09353 | J43: =IF(OR(ISBLANK(Instructions!$D$34),I17="Not Valid"),"",IF(Instructions!$D$34="Megalitres (thousand cubic metres)","ML",IF(Instructions!$D$34="Acre-feet", "acre-feet","million gallons"))&"/year") -> million gallons/year
C45: Infrastructure Leakage Index (ILI) [CARL/UARL]: | I45: =IF(ISERROR(1/I17),"",I43/I17) -> 3.1111015
C46: ="* This performance indicator applies for systems with a low service connection density of less than "&IF(Instructions!D34="Megalitres (thousand cubic metres)",20,32)&" service connections/"&IF(Instructions!D34="Megalitres (thousand cubic metres)","kilometre","mile")&" of pipeline" -> * This performance indicator applies for systems with a low service connection density of less than 32 service connections/mile of pipeline

Sheet Comments
B2: AWWA Free Water Audit Software: User Comments
B3: Use this worksheet to add comments or notes to explain how an input value was calculated, or to document the sources of the information used.
B5: General Comment:
B7: Audit Item | C7: Comment
B8: Volume from own sources:
B9: Vol. from own sources: Master meter error adjustment:
B10: Water imported:
B11: Water imported: master meter error adjustment:
B12: Water exported:
B13: Water exported: master meter error adjustment:
B14: Billed metered:
B15: Billed unmetered:
B16: Unbilled metered:
B17: Unbilled unmetered:
B18: Unauthorized consumption:
B19: Customer metering inaccuracies:
... B27: Variable production cost (applied to Real Losses):

Sheet Water Balance
B2: AWWA Free Water Audit Software: Water Balance
E5: Water Audit Report for: | F5: =IF(ISBLANK(Instructions!D18),"<< Please enter system details and contact information on the Instructions tab >>",Instructions!D18&IF(ISBLANK(Instructions!D36),""," ("&Instructions!D36&")")) -> Suez Water DE
E6: Reporting Year: | F6: =IF(ISBLANK(Instructions!D26),"",Instructions!D26) -> 2020 | G6: =IF(ISBLANK(Instructions!D26),"",IF(Instructions!E26="Calendar Year","1/"&Instructions!D26&" - "&"12/"&Instructions!D26,IF(OR(ISBLANK(Instructions!D28),ISBLANK(Instructions!D30)),"",MONTH(Instructions!D28)&"/"&YEAR(Instructions!D28)&" - "&MONTH(Instructions!D30)&"/"&YEAR(Instructions!D30)))) -> 1/2020 - 12/2020
E7: Data Validity Score: | F7: =IF(ISBLANK(Instructions!$D$34),"N/A*",IF(GradingAssessment!M24>0,"N/A*",ROUND(GradingAssessment!G24,0))) -> 70 | G7: =IF(F7="N/A*","* Confirm Units and Data Grading are Complete","")
D9: Water Exported | G9: Billed Water Exported | H9: Revenue Water
D10: =IF('Reporting Worksheet'!G17>0,IF('Reporting Worksheet'!R17=1,'Reporting Worksheet'!G17/(1+'Reporting Worksheet'!L17),'Reporting Worksheet'!G17-'Reporting Worksheet'!N17),0) -> 54.335 | H10: =D10 -> 54.335
F11: Billed Authorized Consumption | G11: Billed Metered Consumption (water exported is removed) | H11: Revenue Water | K11: Data for plotting the Water Balance with volume-proportional bars on the Dashboard
G12: ='Reporting Worksheet'!G23 -> 4440.547
B13: Own Sources | E13: Authorized Consumption | F13: ='Reporting Worksheet'!G23+'Reporting Worksheet'!G24 -> 4440.547 | G13: Billed Unmetered Consumption | H13: =SUM(G12+G14) -> 4440.547 | K13: Volume From Own Sources | L13: ='Water Balance'!B17 -> 5243.759
B14: (Adjusted for known errors) | G14: ='Reporting Worksheet'!G24 -> 0 | K14: Water Imported | L14: ='Water Balance'!B27 -> 233.6473
E15: ='Reporting Worksheet'!G30 -> 4562.3187 | F15: Unbilled Authorized Consumption | G15: Unbilled Metered Consumption | H15: Non-Revenue Water (NRW) | K15: Water Exported | L15: ='Water Balance'!D10 -> 54.335 | M15: ='Water Balance'!D10 -> 54.335 | N15: ='Water Balance'!D10 -> 54.335 | O15: ='Water Balance'!D10 -> 54.335 | P15: ='Water Balance'!D10 -> 54.335
G16: ='Reporting Worksheet'!G25 -> 53.98333 | K16: Water Supplied | M16: ='Water Balance'!D21 -> 5423.0713
B17: =IF('Reporting Worksheet'!R15>0,IF('Reporting Worksheet'!R15=1,'Reporting Worksheet'!G15/(1+'Reporting Worksheet'!L15),'Reporting Worksheet'!G15-'Reporting Worksheet'!N15),0) -> 5243.759 | F17: ='Reporting Worksheet'!G25+'Reporting Worksheet'!G26 -> 121.77172 | G17: Unbilled Unmetered Consumption | K17: Authorized Consumption | N17: ='Water Balance'!E15 -> 4562.3187
G18: ='Reporting Worksheet'!G26 -> 67.788391 | K18: Water Losses | N18: ='Water Balance'!E25 -> 860.75258
C19: System Input | D19: Water Supplied | G19: Unauthorized Consumption | H19: ='Reporting Worksheet'!G25+'Reporting Worksheet'!G26+'Reporting Worksheet'!G47+'Reporting Worksheet'!G52 -> 982.5243 | K19: Billed Auth. Cons. | O19: ='Water Balance'!F13 -> 4440.547
C20: =B17+B27 -> 5477.4063 | F20: Apparent Losses | G20: ='Reporting Worksheet'!G38 -> 13.557678 | K20: Unbilled Auth. Cons. | O20: ='Water Balance'!F17 -> 121.77172
D21: ='Reporting Worksheet'!G19 -> 5423.0713 | F21: ='Reporting Worksheet'!G47 -> 24.659046 | G21: Customer Metering Inaccuracies | K21: Apparent Losses | O21: ='Water Balance'!F21 -> 24.659046
G22: ='Reporting Worksheet'!G42 -> 0 | K22: Real Losses | O22: ='Water Balance'!F27 -> 836.09353
G23: Systematic Data Handling Errors | K23: Revenue Water | P23: ='Water Balance'!H13 -> 4440.547
E24: Water Losses | G24: ='Reporting Worksheet'!G43 -> 11.101367 | K24: Non Revenue Water | P24: ='Water Balance'!H19 -> 982.5243
B25: Water Imported | E25: ='Reporting Worksheet'!G54 -> 860.75258 | G25: Leakage on Transmission and/or Distribution Mains | L25: =L13+L14 -> 5477.4063 | M25: =SUM(M13:M24) -> 5477.4063 | N25: =SUM(N13:N24) -> 5477.4063 | O25: =SUM(O13:O24) -> 5477.4063 | P25: =SUM(P13:P24) -> 5477.4063
F26: Real Losses | G26: Not broken down
B27: =IF('Reporting Worksheet'!G16>0,IF('Reporting Worksheet'!R16=1,'Reporting Worksheet'!G16/(1+'Reporting Worksheet'!L16),'Reporting Worksheet'!G16-'Reporting Worksheet'!N16),0) -> 233.6473 | F27: ='Reporting Worksheet'!G52 -> 836.09353 | G27: Leakage and Overflows at Utility's Storage Tanks
G28: Not broken down
G29: Leakage on Service Connections
G30: Not broken down

Sheet GradingAssessment
G2: Score
C3: Grade | D3: Weight | E3: adjWeight | F3: adjFactor | G3: Grade*Weight | H3: droppedPts | I3: uniqueRank | K3: Needs grade | L3: Has grade | M3: Grade Problem
B4: Volume from own sources: | C4: =IF('Reporting Worksheet'!E15="n/a",0,'Reporting Worksheet'!E15) -> 7 | D4: ='Reporting Worksheet'!T15 -> 33.177901 | E4: =D4 -> 33.177901 | F4: =IF(D4<>0,E4/10,0) -> 3.3177901 | G4: =C4*F4 -> 23.224531 | H4: =IF(F4=0,0,E4-G4) -> 9.9533703 | I4: {=SUM(1*(H4<$H$4:$H$23))+1+IF(ROW(H4)-ROW($H$4)=0,0,SUM(1*(H4=OFFSET($H$4,0,0,INDEX(ROW(H4)-ROW($H$4)+1,1)-1,1))))} -> 1 | J4: Volume from own sources | K4: =IF(D4<>0,1,0) -> 1 | L4: =IF(C4>0,1,0) -> 1 | M4: =IF(AND(K4=1,L4=0),1,0) -> 0
B5: Volume from own sources master meter error adjustment: | C5: =IF('Reporting Worksheet'!J15="n/a",0,'Reporting Worksheet'!J15) -> 0 | D5: ='Reporting Worksheet'!U15 -> 0 | E5: =D5 -> 0 | F5: =IF(D5<>0,E5/10,0) -> 0 | G5: =C5*F5 -> 0 | H5: =IF(F5=0,0,E5-G5) -> 0 | I5: {=SUM(1*(H5<$H$4:$H$23))+1+IF(ROW(H5)-ROW($H$4)=0,0,SUM(1*(H5=OFFSET($H$4,0,0,INDEX(ROW(H5)-ROW($H$4)+1,1)-1,1))))} -> 16 | J5: Master meter error adjustment | K5: =IF(D5<>0,1,0) -> 0 | L5: =IF(C5>0,1,0) -> 0 | M5: =IF(AND(K5=1,L5=0),1,0) -> 0
B6: Water imported: | C6: =IF('Reporting Worksheet'!E16="n/a",0,'Reporting Worksheet'!E16) -> 9 | D6: ='Reporting Worksheet'!T16 -> 1.4783149 | E6: =D6 -> 1.4783149 | F6: =IF(D6<>0,E6/10,0) -> 0.14783149 | G6: =C6*F6 -> 1.3304834 | H6: =IF(F6=0,0,E6-G6) -> 0.14783149 | I6: {=SUM(1*(H6<$H$4:$H$23))+1+IF(ROW(H6)-ROW($H$4)=0,0,SUM(1*(H6=OFFSET($H$4,0,0,INDEX(ROW(H6)-ROW($H$4)+1,1)-1,1))))} -> 14 | J6: Water imported | K6: =IF(D6<>0,1,0) -> 1 | L6: =IF(C6>0,1,0) -> 1 | M6: =IF(AND(K6=1,L6=0),1,0) -> 0
B7: Water imported meter error adjustment: | C7: =IF('Reporting Worksheet'!J16="n/a",0,'Reporting Worksheet'!J16) -> 0 | D7: ='Reporting Worksheet'!U16 -> 0 | E7: =D7 -> 0 | F7: =IF(D7<>0,E7/10,0) -> 0 | G7: =C7*F7 -> 0 | H7: =IF(F7=0,0,E7-G7) -> 0 | I7: {=SUM(1*(H7<$H$4:$H$23))+1+IF(ROW(H7)-ROW($H$4)=0,0,SUM(1*(H7=OFFSET($H$4,0,0,INDEX(ROW(H7)-ROW($H$4)+1,1)-1,1))))} -> 17 | J7: Master meter error adjustment (Import) | K7: =IF(D7<>0,1,0) -> 0 | L7: =IF(C7>0,1,0) -> 0 | M7: =IF(AND(K7=1,L7=0),1,0) -> 0
B8: Water exported: | C8: =IF('Reporting Worksheet'!E17="n/a",0,'Reporting Worksheet'!E17) -> 2 | D8: ='Reporting Worksheet'!T17 -> 0.34378415 | E8: =D8 -> 0.34378415 | F8: =IF(D8<>0,E8/10,0) -> 0.034378415 | G8: =C8*F8 -> 0.068756831 | H8: =IF(F8=0,0,E8-G8) -> 0.27502732 | I8: {=SUM(1*(H8<$H$4:$H$23))+1+IF(ROW(H8)-ROW($H$4)=0,0,SUM(1*(H8=OFFSET($H$4,0,0,INDEX(ROW(H8)-ROW($H$4)+1,1)-1,1))))} -> 13 | J8: Water exported | K8: =IF(D8<>0,1,0) -> 1 | L8: =IF(C8>0,1,0) -> 1 | M8: =IF(AND(K8=1,L8=0),1,0) -> 0
B9: Water exported meter error adjustment: | C9: =IF('Reporting Worksheet'!J17="n/a",0,'Reporting Worksheet'!J17) -> 0 | D9: ='Reporting Worksheet'!U17 -> 0 | E9: =D9 -> 0 | F9: =IF(D9<>0,E9/10,0) -> 0 | G9: =C9*F9 -> 0 | H9: =IF(F9=0,0,E9-G9) -> 0 | I9: {=SUM(1*(H9<$H$4:$H$23))+1+IF(ROW(H9)-ROW($H$4)=0,0,SUM(1*(H9=OFFSET($H$4,0,0,INDEX(ROW(H9)-ROW($H$4)+1,1)-1,1))))} -> 18 | J9: Master meter error adjustment (Export) | K9: =IF(D9<>0,1,0) -> 0 | L9: =IF(C9>0,1,0) -> 0 | M9: =IF(AND(K9=1,L9=0),1,0) -> 0
B10: Billed metered: | C10: =IF('Reporting Worksheet'!E23="n/a",0,'Reporting Worksheet'!E23) -> 9 | D10: =IF(AND('Reporting Worksheet'!E23="n/a",'Reporting Worksheet'!G23=0),0,8) -> 8 | E10: =D10/$D$26 -> 10.196078 | F10: =IF(D10<>0,E10/10,0) -> 1.0196078 | G10: =C10*F10 -> 9.1764706 | H10: =IF(F10=0,0,E10-G10) -> 1.0196078 | I10: {=SUM(1*(H10<$H$4:$H$23))+1+IF(ROW(H10)-ROW($H$4)=0,0,SUM(1*(H10=OFFSET($H$4,0,0,INDEX(ROW(H10)-ROW($H$4)+1,1)-1,1))))} -> 8 | J10: Billed metered | K10: =IF(D10<>0,1,0) -> 1 | L10: =IF(C10>0,1,0) -> 1 | M10: =IF(AND(K10=1,L10=0),1,0) -> 0
B11: Billed unmetered: | C11: =IF('Reporting Worksheet'!E24="n/a",0,'Reporting Worksheet'!E24) -> 0 | D11: =IF('Reporting Worksheet'!G24=0,0,6) -> 0 | E11: =D11/$D$26 -> 0 | F11: =IF(D11<>0,E11/10,0) -> 0 | G11: =C11*F11 -> 0 | H11: =IF(F11=0,0,E11-G11) -> 0 | I11: {=SUM(1*(H11<$H$4:$H$23))+1+IF(ROW(H11)-ROW($H$4)=0,0,SUM(1*(H11=OFFSET($H$4,0,0,INDEX(ROW(H11)-ROW($H$4)+1,1)-1,1))))} -> 19 | J11: Billed unmetered | K11: =IF(D11<>0,1,0) -> 0 | L11: =IF(C11>0,1,0) -> 0 | M11: =IF(AND(K11=1,L11=0),1,0) -> 0
B12: Unbilled metered: | C12: =IF('Reporting Worksheet'!E25="n/a",0,'Reporting Worksheet'!E25) -> 8 | D12: =IF('Reporting Worksheet'!G25=0,0,6) -> 6 | E12: =D12/$D$26 -> 7.6470588 | F12: =IF(D12<>0,E12/10,0) -> 0.76470588 | G12: =C12*F12 -> 6.1176471 | H12: =IF(F12=0,0,E12-G12) -> 1.5294118 | I12: {=SUM(1*(H12<$H$4:$H$23))+1+IF(ROW(H12)-ROW($H$4)=0,0,SUM(1*(H12=OFFSET($H$4,0,0,INDEX(ROW(H12)-ROW($H$4)+1,1)-1,1))))} -> 6 | J12: Unbilled metered | K12: =IF(D12<>0,1,0) -> 1 | L12: =IF(C12>0,1,0) -> 1 | M12: =IF(AND(K12=1,L12=0),1,0) -> 0
A13: D | B13: Unbilled unmetered: | C13: =IF(OR('Reporting Worksheet'!R26=1,AND('Reporting Worksheet'!R26=2,'Reporting Worksheet'!N26=0)),5,'Reporting Worksheet'!E26) -> 5 | D13: 1 | E13: =D13/$D$26 -> 1.2745098 | F13: =IF(D13<>0,E13/10,0) -> 0.12745098 | G13: =C13*F13 -> 0.6372549 | H13: =IF(F13=0,0,E13-G13) -> 0.6372549 | I13: {=SUM(1*(H13<$H$4:$H$23))+1+IF(ROW(H13)-ROW($H$4)=0,0,SUM(1*(H13=OFFSET($H$4,0,0,INDEX(ROW(H13)-ROW($H$4)+1,1)-1,1))))} -> 11 | J13: Unbilled unmetered | K13: =IF(D13<>0,1,0) -> 1 | L13: =IF(C13>0,1,0) -> 1 | M13: =IF(AND(K13=1,L13=0),1,0) -> 0
A14: D | B14: Unauthorized consumption: | C14: =IF(OR('Reporting Worksheet'!R38=1,AND('Reporting Worksheet'!R38=2,'Reporting Worksheet'!N38=0)),5,'Reporting Worksheet'!E38) -> 5 | D14: 4 | E14: =D14/$D$26 -> 5.0980392 | F14: =IF(D14<>0,E14/10,0) -> 0.50980392 | G14: =C14*F14 -> 2.5490196 | H14: =IF(F14=0,0,E14-G14) -> 2.5490196 | I14: {=SUM(1*(H14<$H$4:$H$23))+1+IF(ROW(H14)-ROW($H$4)=0,0,SUM(1*(H14=OFFSET($H$4,0,0,INDEX(ROW(H14)-ROW($H$4)+1,1)-1,1))))} -> 4 | J14: Unauthorized consumption | K14: =IF(D14<>0,1,0) -> 1 | L14: =IF(C14>0,1,0) -> 1 | M14: =IF(AND(K14=1,L14=0),1,0) -> 0
B15: Customer metering inaccuracies: | C15: =IF('Reporting Worksheet'!E42="n/a",0,'Reporting Worksheet'!E42) -> 6 | D15: =IF(AND('Reporting Worksheet'!E42="n/a",'Reporting Worksheet'!G42=0),0,6) -> 6 | E15: =D15/$D$26 -> 7.6470588 | F15: =IF(D15<>0,E15/10,0) -> 0.76470588 | G15: =C15*F15 -> 4.5882353 | H15: =IF(F15=0,0,E15-G15) -> 3.0588235 | I15: {=SUM(1*(H15<$H$4:$H$23))+1+IF(ROW(H15)-ROW($H$4)=0,0,SUM(1*(H15=OFFSET($H$4,0,0,INDEX(ROW(H15)-ROW($H$4)+1,1)-1,1))))} -> 3 | J15: Customer metering inaccuracies | K15: =IF(D15<>0,1,0) -> 1 | L15: =IF(C15>0,1,0) -> 1 | M15: =IF(AND(K15=1,L15=0),1,0) -> 0
B16: Systematic data handling errors: | C16: =IF('Reporting Worksheet'!G43=0,1,IF('Reporting Worksheet'!R43=1,5,'Reporting Worksheet'!E43)) -> 5 | D16: 4 | E16: =D16/$D$26 -> 5.0980392 | F16: =IF(D16<>0,E16/10,0) -> 0.50980392 | G16: =C16*F16 -> 2.5490196 | H16: =IF(F16=0,0,E16-G16) -> 2.5490196 | I16: {=SUM(1*(H16<$H$4:$H$23))+1+IF(ROW(H16)-ROW($H$4)=0,0,SUM(1*(H16=OFFSET($H$4,0,0,INDEX(ROW(H16)-ROW($H$4)+1,1)-1,1))))} -> 5 | J16: Systematic data handling errors | K16: =IF(D16<>0,1,0) -> 1 | L16: =IF(C16>0,1,0) -> 1 | M16: =IF(AND(K16=1,L16=0),1,0) -> 0
B17: Length of mains: | C17: ='Reporting Worksheet'!E62 -> 9 | D17: 1 | E17: =D17/$D$26 -> 1.2745098 | F17: =IF(D17<>0,E17/10,0) -> 0.12745098 | G17: =C17*F17 -> 1.1470588 | H17: =IF(F17=0,0,E17-G17) -> 0.12745098 | I17: {=SUM(1*(H17<$H$4:$H$23))+1+IF(ROW(H17)-ROW($H$4)=0,0,SUM(1*(H17=OFFSET($H$4,0,0,INDEX(ROW(H17)-ROW($H$4)+1,1)-1,1))))} -> 15 | J17: Length of mains | K17: =IF(D17<>0,1,0) -> 1 | L17: =IF(C17>0,1,0) -> 1 | M17: =IF(AND(K17=1,L17=0),1,0) -> 0
B18: Number of active AND inactive service connections: | C18: ='Reporting Worksheet'!E63 -> 6 | D18: 1 | E18: =D18/$D$26 -> 1.2745098 | F18: =IF(D18<>0,E18/10,0) -> 0.12745098 | G18: =C18*F18 -> 0.76470588 | H18: =IF(F18=0,0,E18-G18) -> 0.50980392 | I18: {=SUM(1*(H18<$H$4:$H$23))+1+IF(ROW(H18)-ROW($H$4)=0,0,SUM(1*(H18=OFFSET($H$4,0,0,INDEX(ROW(H18)-ROW($H$4)+1,1)-1,1))))} -> 12 | J18: Number of active AND inactive service connections | K18: =IF(D18<>0,1,0) -> 1 | L18: =IF(C18>0,1,0) -> 1 | M18: =IF(AND(K18=1,L18=0),1,0) -> 0
B19: Average length of customer service line: | C19: ='Reporting Worksheet'!R67 -> 4 | D19: 1 | E19: =D19/$D$26 -> 1.2745098 | F19: =IF(D19<>0,E19/10,0) -> 0.12745098 | G19: =C19*F19 -> 0.50980392 | H19: =IF(F19=0,0,E19-G19) -> 0.76470588 | I19: {=SUM(1*(H19<$H$4:$H$23))+1+IF(ROW(H19)-ROW($H$4)=0,0,SUM(1*(H19=OFFSET($H$4,0,0,INDEX(ROW(H19)-ROW($H$4)+1,1)-1,1))))} -> 9 | J19: Average length of customer service line | K19: =IF(D19<>0,1,0) -> 1 | L19: =IF(C19>0,1,0) -> 1 | M19: =IF(AND(K19=1,L19=0),1,0) -> 0
B20: Average operating pressure: | C20: ='Reporting Worksheet'!E69 -> 4 | D20: 1 | E20: =D20/$D$26 -> 1.2745098 | F20: =IF(D20<>0,E20/10,0) -> 0.12745098 | G20: =C20*F20 -> 0.50980392 | H20: =IF(F20=0,0,E20-G20) -> 0.76470588 | I20: {=SUM(1*(H20<$H$4:$H$23))+1+IF(ROW(H20)-ROW($H$4)=0,0,SUM(1*(H20=OFFSET($H$4,0,0,INDEX(ROW(H20)-ROW($H$4)+1,1)-1,1))))} -> 10 | J20: Average operating pressure | K20: =IF(D20<>0,1,0) -> 1 | L20: =IF(C20>0,1,0) -> 1 | M20: =IF(AND(K20=1,L20=0),1,0) -> 0
B21: Total annual cost of operating water system: | C21: ='Reporting Worksheet'!E76 -> 10 | D21: 6 | E21: =D21/$D$26 -> 7.6470588 | F21: =IF(D21<>0,E21/10,0) -> 0.76470588 | G21: =C21*F21 -> 7.6470588 | H21: =IF(F21=0,0,E21-G21) -> 0 | I21: {=SUM(1*(H21<$H$4:$H$23))+1+IF(ROW(H21)-ROW($H$4)=0,0,SUM(1*(H21=OFFSET($H$4,0,0,INDEX(ROW(H21)-ROW($H$4)+1,1)-1,1))))} -> 20 | J21: Total annual cost of operating water system | K21: =IF(D21<>0,1,0) -> 1 | L21: =IF(C21>0,1,0) -> 1 | M21: =IF(AND(K21=1,L21=0),1,0) -> 0
B22: Customer retail unit cost (applied to Apparent Losses): | C22: ='Reporting Worksheet'!E77 -> 8 | D22: 6 | E22: =D22/$D$26 -> 7.6470588 | F22: =IF(D22<>0,E22/10,0) -> 0.76470588 | G22: =C22*F22 -> 6.1176471 | H22: =IF(F22=0,0,E22-G22) -> 1.5294118 | I22: {=SUM(1*(H22<$H$4:$H$23))+1+IF(ROW(H22)-ROW($H$4)=0,0,SUM(1*(H22=OFFSET($H$4,0,0,INDEX(ROW(H22)-ROW($H$4)+1,1)-1,1))))} -> 7 | J22: Customer retail unit cost (applied to Apparent Losses) | K22: =IF(D22<>0,1,0) -> 1 | L22: =IF(C22>0,1,0) -> 1 | M22: =IF(AND(K22=1,L22=0),1,0) -> 0
B23: Variable production cost (applied to Real Losses): | C23: =IF('Reporting Worksheet'!E78="n/a",0,'Reporting Worksheet'!E78) -> 4 | D23: 6 | E23: =D23/$D$26 -> 7.6470588 | F23: =IF(D23<>0,E23/10,0) -> 0.76470588 | G23: =C23*F23 -> 3.0588235 | H23: =IF(F23=0,0,E23-G23) -> 4.5882353 | I23: {=SUM(1*(H23<$H$4:$H$23))+1+IF(ROW(H23)-ROW($H$4)=0,0,SUM(1*(H23=OFFSET($H$4,0,0,INDEX(ROW(H23)-ROW($H$4)+1,1)-1,1))))} -> 2 | J23: Variable production cost (applied to Real Losses) | K23: =IF(D23<>0,1,0) -> 1 | L23: =IF(C23>0,1,0) -> 1 | M23: =IF(AND(K23=1,L23=0),1,0) -> 0
D24: =SUM(D4:D23) -> 86 | E24: =SUM(E4:E23) -> 100 | F24: =SUM(F4:F23) -> 10 | G24: =SUM(G4:G23) -> 69.99632 | M24: =SUM(M4:M23) -> 0
D25: =SUM(D10:D23) -> 51
D26: =D25/(100-D27) -> 0.78461538
C27: Total Pts for Water Supplied (top 6 items): | D27: 35 | L27: =IF(SUM('Reporting Worksheet'!R26,'Reporting Worksheet'!R38)=2,2,IF(SUM('Reporting Worksheet'!R26,'Reporting Worksheet'!R38)=3,1,0)) -> 2 | M27: default(s) being used

Sheet Dashboard
B2: AWWA Free Water Audit Software: Dashboard
F4: Water Audit Report for: | G4: =IF(ISBLANK(Instructions!D18),"<< Please enter system details and contact information on the Instructions tab >>",Instructions!D18&IF(ISBLANK(Instructions!D36),""," ("&Instructions!D36&")")) -> Suez Water DE
F5: Reporting Year: | G5: =IF(ISBLANK(Instructions!D26),"",Instructions!D26) -> 2020 | H5: =IF(ISBLANK(Instructions!D26),"",IF(Instructions!E26="Calendar Year","1/"&Instructions!D26&" - "&"12/"&Instructions!D26,IF(OR(ISBLANK(Instructions!D28),ISBLANK(Instructions!D30)),"",MONTH(Instructions!D28)&"/"&YEAR(Instructions!D28)&" - "&MONTH(Instructions!D30)&"/"&YEAR(Instructions!D30)))) -> 1/2020 - 12/2020 | N5: Show me the VOLUME of Non-Revenue Water
F6: Data Validity Score: | G6: =IF(ISBLANK(Instructions!$D$34),"N/A*",IF(GradingAssessment!M24>0,"N/A*",ROUND(GradingAssessment!G24,0))) -> 70 | H6: =IF(G6="N/A*","* Confirm Units and Data Grading are Complete","") | N6: Show me the COST of Non-Revenue Water | S6: 1

Sheet Grading Matrix
C2: AWWA Free Water Audit Software: Grading Matrix | R2: =VLOOKUP(1,GradingAssessment!$I$4:$J$23,2,FALSE)&":" -> Volume from own sources:
C4: The grading assigned to each audit component and the corresponding recommended improvements and actions are highlighted in yellow. Audit accuracy is likely to be improved by prioritizing those items shown in red | R4: =VLOOKUP(2,GradingAssessment!$I$4:$J$23,2,FALSE)&":" -> Variable production cost (applied to Real Losses):
C7: Grading >>> | D7: n/a | E7: 1 | F7: 2 | G7: 3 | H7: 4 | I7: 5 | J7: 6 | K7: 7 | L7: 8 | M7: 9 | N7: 10 | R7: =VLOOKUP(3,GradingAssessment!$I$4:$J$23,2,FALSE)&":" -> Customer metering inaccuracies:
D8: WATER SUPPLIED
C9: Volume from own sources: | D9: Select this grading only if the water utility purchases/imports all of its water resources (i.e. has no sources of its own) | E9: Less than 25% of water production sources are metered, remaining sources are estimated. No regular meter accuracy testing or electronic calibration conducted. | F9: 25% - 50% of treated water production sources are metered; other sources estimated. No regular meter accuracy testing or electronic calibration conducted. | G9: Conditions between 2 and 4 | H9: 50% - 75% of treated water production sources are metered, other sources estimated. Occasional meter accuracy testing or electronic calibration conducted. | I9: Conditions between 4 and 6 | J9: At least 75% of treated water production sources are metered, or at least 90% of the source flow is derived from metered sources. Meter accuracy testing and/or electronic calibration of related instrumentation is conducted annually. Less than 25% of tested meters are found outside of +/- 6% accuracy. | K9: Conditions between 6 and 8 | L9: 100% of treated water production sources are metered, meter accuracy testing and electronic calibration of related instrumentation is conducted annually, less than 10% of meters are found outside of +/- 6% accuracy | M9: Conditions between 8 and 10 | N9: 100% of treated water production sources are metered, meter accuracy testing and electronic calibration of related instrumentation is conducted semi-annually, with less than 10% found outside of +/- 3% accuracy. Procedures are reviewed by a third party knowledgeable in the M36 methodology. | Q9: ='Reporting Worksheet'!E15 -> 7 | R9: =IF(OR(C9=$R$2,C9=$R$4,C9=$R$7),1,0) -> 1
C10: Improvements to attain higher data grading for "Volume from own Sources" component: | E10: to qualify for 2: Organize and launch efforts to collect data for determining volume from own sources | F10: to qualify for 4: Locate all water production sources on maps and in the field, launch meter accuracy testing for existing meters, begin to install meters on unmetered water production sources and replace any obsolete/defective meters. | H10: to qualify for 6: Formalize annual meter accuracy testing for all source meters; specify the frequency of testing. Complete installation of meters on unmetered water production sources and complete replacement of all obsolete/defective meters. | J10: to qualify for 8: Conduct annual meter accuracy testing and calibration of related instrumentation on all meter installations on a regular basis. Complete project to install new, or replace defective existing, meters so that entire production meter population is metered. Repair or replace meters outside of +/- 6% accuracy. | L10: to qualify for 10: Maintain annual meter accuracy testing and calibration of related instrumentation for all meter installations. Repair or replace meters outside of +/- 3% accuracy. Investigate new meter technology; pilot one or more replacements with innovative meters in attempt to further improve meter accuracy. | N10: to maintain 10: Standardize meter accuracy test frequency to semi-annual, or more frequent, for all meters. Repair or replace meters outside of +/- 3% accuracy. Continually investigate/pilot improving metering technology. | Q10: =Q9 -> 7
C11: Volume from own sources master meter and supply error adjustment: | D11: Select n/a only if the water utility fails to have meters on its sources of supply | E11: Inventory information on meters and paper records of measured volumes exist but are incomplete and/or in a very crude condition; data error cannot be determined | F11: No automatic datalogging of production volumes; daily readings are scribed on paper records without any accountability controls. Flows are not balanced across the water distribution system: tank/storage elevation changes are not employed in calculating the "Volume from own sources" component and archived flow data is adjusted only when grossly evident data error occurs. | G11: Conditions between 2 and 4 | H11: Production meter data is logged automatically in electronic format and reviewed at least on a monthly basis with necessary corrections implemented. "Volume from own sources" tabulations include estimate of daily changes in tanks/storage facilities. Meter data is adjusted when gross data errors occur, or occasional meter testing deems this necessary. | I11: Conditions between 4 and 6 | J11: Hourly production meter data logged automatically & reviewed on at least a weekly basis. Data is adjusted to correct gross error when meter/instrumentation equipment malfunction is detected; and/or error is confirmed by meter accuracy testing. Tank/storage facility elevation changes are automatically used in calculating a balanced "Volume from own sources" component, and data gaps in the archived data are corrected on at least a weekly basis. | K11: Conditions between 6 and 8 | L11: Continuous production meter data is logged automatically & reviewed each business day. Data is adjusted to correct gross error from detected meter/instrumentation equipment malfunction and/or results of meter accuracy testing. Tank/storage facility elevation changes are automatically used in "Volume from own sources" tabulations and data gaps in the archived data are corrected on a daily basis. | M11: Conditions between 8 and 10 | N11: Computerized system (SCADA or similar) automatically balances flows from all sources and storages; results are reviewed each business day. Tight accountability controls ensure that all data gaps that occur in the archived flow data are quickly detected and corrected. Regular calibrations between SCADA and sources meters ensures minimal data transfer error. | Q11: ='Reporting Worksheet'!J15 -> 0 | R11: =IF(OR(C11=$R$2,C11=$R$4,C11=$R$7),1,0) -> 0
C12: Improvements to attain higher data grading for "Master meter and supply error adjustment" component: | E12: to qualify for 2: Develop a plan to restructure recordkeeping system to capture all flow data; set a procedure to review flow data on a daily basis to detect input errors. Obtain more reliable information about existing meters by conducting field inspections of meters and related instrumentation, and obtaining manufacturer literature. | F12: to qualify for 4: Install automatic datalogging equipment on production meters. Complete installation of level instrumentation at all tanks/storage facilities and include tank level data in automatic calculation routine in a computerized system. Construct a computerized listing or spreadsheet to archive input volumes, tank/storage volume changes and import/export flows in order to determine the composite "Water Supplied" volume for the distribution system. Set a procedure to review this data on a monthly basis to detect gross anomalies and data gaps. | H12: to qualify for 6: Refine computerized data collection and archive to include hourly production meter data that is reviewed at least on a weekly basis to detect specific data anomalies and gaps. Use daily net storage change to balance flows in calculating "Water Supplied" volume. Necessary corrections to data errors are implemented on a weekly basis. | J12: to qualify for 8: Ensure that all flow data is collected and archived on at least an hourly basis. All data is reviewed and detected errors corrected each business day. Tank/storage levels variations are employed in calculating balanced "Water Supplied" component. Adjust production meter data for gross error and inaccuracy confirmed by testing. | L12: to qualify for 10: Link all production and tank/storage facility elevation change data to a Supervisory Control & Data Acquisition (SCADA) System, or similar computerized monitoring/control system, and establish automatic flow balancing algorithm and regularly calibrate between SCADA and source meters. Data is reviewed and corrected each business day. | N12: to maintain 10: Monitor meter innovations for development of more accurate and less expensive flowmeters. Continue to replace or repair meters as they perform outside of desired accuracy limits. Stay abreast of new and more accurate water level instruments to better record tank/storage levels and archive the variations in storage volume. Keep current with SCADA and data management systems to ensure that archived data is well-managed and error free. | Q12: =Q11 -> 0
C13: Water Imported: | D13: Select n/a if the water utility's supply is exclusively from its own water resources (no bulk purchased/ imported water) | E13: Less than 25% of imported water sources are metered, remaining sources are estimated. No regular meter accuracy testing. | F13: 25% - 50% of imported water sources are metered; other sources estimated. No regular meter accuracy testing. | G13: Conditions between 2 and 4 | H13: 50% - 75% of imported water sources are metered, other sources estimated. Occasional meter accuracy testing conducted. | I13: Conditions between 4 and 6 | J13: At least 75% of imported water sources are metered, meter accuracy testing and/or electronic calibration of related instrumentation is conducted annually for all meter installations. Less than 25% of tested meters are found outside of +/- 6% accuracy. | K13: Conditions between 6 and 8 | L13: 100% of imported water sources are metered, meter accuracy testing and electronic calibration of related instrumentation is conducted annually, less than 10% of meters are found outside of +/- 6% accuracy | M13: Conditions between 8 and 10 | N13: 100% of imported water sources are metered, meter accuracy testing and electronic calibration of related instrumentation is conducted semi-annually for all meter installations, with less than 10% of accuracy tests found outside of +/- 3% accuracy. | Q13: ='Reporting Worksheet'!E16 -> 9 | R13: =IF(OR(C13=$R$2,C13=$R$4,C13=$R$7),1,0) -> 0
C14: Improvements to attain higher data grading for "Water Imported Volume" component: (Note: usually the water supplier selling the water - "the Exporter" - to the utility being audited is responsible to maintain the metering installation measuring the imported volume. The utility should coordinate carefully with the Exporter to ensure that adequate meter upkeep takes place and an accurate measure of the Water Imported volume is quantified.) | E14: to qualify for 2: Review bulk water purchase agreements with partner suppliers; confirm requirements for use and maintenance of accurate metering. Identify needs for new or replacement meters with goal to meter all imported water sources. | F14: To qualify for 4: Locate all imported water sources on maps and in the field, launch meter accuracy testing for existing meters, begin to install meters on unmetered imported water interconnections and replace obsolete/defective meters. | H14: to qualify for 6: Formalize annual meter accuracy testing for all imported water meters, planning for both regular meter accuracy testing and calibration of the related instrumentation. Continue installation of meters on unmetered imported water interconnections and replacement of obsolete/defective meters. | J14: to qualify for 8: Complete project to install new, or replace defective, meters on all imported water interconnections. Maintain annual meter accuracy testing for all imported water meters and conduct calibration of related instrumentation at least annually. Repair or replace meters outside of +/- 6% accuracy. | L14: to qualify for 10: Conduct meter accuracy testing for all meters on a semi-annual basis, along with calibration of all related instrumentation. Repair or replace meters outside of +/- 3% accuracy. Investigate new meter technology; pilot one or more replacements with innovative meters in attempt to improve meter accuracy. | N14: to maintain 10: Standardize meter accuracy test frequency to semi-annual, or more frequent, for all meters. Continue to conduct calibration of related instrumentation on a semi-annual basis. Repair or replace meters outside of +/- 3% accuracy. Continually investigate/pilot improving metering technology. | Q14: =Q13 -> 9
C15: Water imported master meter and supply error adjustment: | D15: Select n/a if the Imported water supply is unmetered, with Imported water quantities estimated on the billing invoices sent by the Exporter to the purchasing Utility. | E15: Inventory information on imported meters and paper records of measured volumes exist but are incomplete and/or in a very crude condition; data error cannot be determined Written agreement(s) with water Exporter(s) are missing or written in vague language concerning meter management and testing. | F15: No automatic datalogging of imported supply volumes; daily readings are scribed on paper records without any accountability controls to confirm data accuracy and the absence of errors and data gaps in recorded volumes. Written agreement requires meter accuracy testing but is vague on the details of how and who conducts the testing. | G15: Conditions between 2 and 4 | H15: Imported supply metered flow data is logged automatically in electronic format and reviewed at least on a monthly basis by the Exporter with necessary corrections implemented. Meter data is adjusted by the Exporter when gross data errors are detected. A coherent data trail exists for this process to protect both the selling and the purchasing Utility. Written agreement exists and clearly states requirements and roles for meter accuracy testing and data management. | I15: Conditions between 4 and 6 | J15: Hourly Imported supply metered data is logged automatically & reviewed on at least a weekly basis by the Exporter. Data is adjusted to correct gross error when meter/instrumentation equipment malfunction is detected; and to correct for error confirmed by meter accuracy testing. Any data gaps in the archived data are detected and corrected during the weekly review. A coherent data trail exists for this process to protect both the selling and the purchasing Utility. | K15: Conditions between 6 and 8 | L15: Continuous Imported supply metered flow data is logged automatically & reviewed each business day by the Exporter. Data is adjusted to correct gross error from detected meter/instrumentation equipment malfunction and/or results of meter accuracy testing. Any data errors/gaps are detected and corrected on a daily basis. A data trail exists for the process to protect both the selling and the purchasing Utility. | M15: Conditions between 8 and 10 | N15: Computerized system (SCADA or similar) automatically records data which is reviewed each business day by the Exporter. Tight accountability controls ensure that all error/data gaps that occur in the archived flow data are quickly detected and corrected. A reliable data trail exists and contract provisions for meter testing and data management are reviewed by the selling and purchasing Utility at least once every five years. | Q15: ='Reporting Worksheet'!J16 -> 0 | R15: =IF(OR(C15=$R$2,C15=$R$4,C15=$R$7),1,0) -> 0
C16: Improvements to attain higher data grading for "Water imported master meter and supply error adjustment" component: | E16: to qualify for 2: Develop a plan to restructure recordkeeping system to capture all flow data; set a procedure to review flow data on a daily basis to detect input errors. Obtain more reliable information about existing meters by conducting field inspections of meters and related instrumentation, and obtaining manufacturer literature. Review the written agreement between the selling and purchasing Utility. | F16: to qualify for 4: Install automatic datalogging equipment on Imported supply meters. Set a procedure to review this data on a monthly basis to detect gross anomalies and data gaps. Launch discussions with the Exporters to jointly review terms of the written agreements regarding meter accuracy testing and data management; revise the terms as necessary. | H16: to qualify for 6: Refine computerized data collection and archive to include hourly Imported supply metered flow data that is reviewed at least on a weekly basis to detect specific data anomalies and gaps. Make necessary corrections to errors/data errors on a weekly basis. | J16: to qualify for 8: Ensure that all Imported supply metered flow data is collected and archived on at least an hourly basis. All data is reviewed and errors/data gaps are corrected each business day. | L16: to qualify for 10: Conduct accountability checks to confirm that all Imported supply metered data is reviewed and corrected each business day by the Exporter. Results of all meter accuracy tests and data corrections should be available for sharing between the Exporter and the purchasing Utility. Establish a schedule for a regular review and updating of the contractual language in the written agreement between the selling and the purchasing Utility; at least every five years. | N16: to maintain 10: Monitor meter innovations for development of more accurate and less expensive flowmeters; work with the Exporter to help identify meter replacement needs. Keep communication lines with Exporters open and maintain productive relations. Keep the written agreement current with clear and explicit language that meets the ongoing needs of all parties. | Q16: =Q15 -> 0
C17: Water Exported: | D17: Select n/a if the water utility sells no bulk water to neighboring water utilities (no exported water sales) | E17: Less than 25% of exported water sources are metered, remaining sources are estimated. No regular meter accuracy testing. | F17: 25% - 50% of exported water sources are metered; other sources estimated. No regular meter accuracy testing. | G17: Conditions between 2 and 4 | H17: 50% - 75% of exported water sources are metered, other sources estimated. Occasional meter accuracy testing conducted. | I17: Conditions between 4 and 6 | J17: At least 75% of exported water sources are metered, meter accuracy testing and/or electronic calibration conducted annually. Less than 25% of tested meters are found outside of +/- 6% accuracy. | K17: Conditions between 6 and 8 | L17: 100% of exported water sources are metered, meter accuracy testing and electronic calibration of related instrumentation is conducted annually, less than 10% of meters are found outside of +/- 6% accuracy | M17: Conditions between 8 and 10 | N17: 100% of exported water sources are metered, meter accuracy testing and electronic calibration of related instrumentation is conducted semi-annually for all meter installations, with less than 10% of accuracy tests found outside of +/- 3% accuracy. | Q17: ='Reporting Worksheet'!E17 -> 2 | R17: =IF(OR(C17=$R$2,C17=$R$4,C17=$R$7),1,0) -> 0
